2025-09-08 14:48:29.132246 - initiating W3...
2025-09-08 14:48:29.153280 - uniswap fully initiated
2025-09-08 14:48:29.154279 - check_balance...
2025-09-08 14:48:29.156280 - eth_balance...
2025-09-08 14:48:30.004215 - weth_balance...
2025-09-08 14:48:30.684320 - dai_balance...
2025-09-08 14:48:31.337087 - wbtc_balance...
2025-09-08 14:48:31.995687 - wsol_balance...
2025-09-08 14:48:32.659004 - usdc_balance...
2025-09-08 14:48:33.302037 - usdt_balance...
2025-09-08 15:05:11.808929 - initiating W3...
2025-09-08 15:05:11.827055 - uniswap fully initiated
2025-09-08 15:05:11.829018 - check_balance...
2025-09-08 15:05:11.829018 - eth_balance...
2025-09-08 15:05:12.815665 - weth_balance...
2025-09-08 15:05:13.462058 - dai_balance...
2025-09-08 15:05:14.123359 - wbtc_balance...
2025-09-08 15:05:14.782033 - wsol_balance...
2025-09-08 15:05:15.426622 - usdc_balance...
2025-09-08 15:05:16.082323 - usdt_balance...
2025-09-08 15:06:25.527203 - initiating W3...
2025-09-08 15:06:25.545223 - uniswap fully initiated
2025-09-08 15:06:25.546219 - check_balance...
2025-09-08 15:06:25.547220 - eth_balance...
2025-09-08 15:06:26.614219 - weth_balance...
2025-09-08 15:06:27.267033 - dai_balance...
2025-09-08 15:06:27.914182 - wbtc_balance...
2025-09-08 15:06:28.553243 - wsol_balance...
2025-09-08 15:06:29.201234 - usdc_balance...
2025-09-08 15:06:29.842426 - usdt_balance...
2025-09-08 15:06:52.217259 - initiating W3...
2025-09-08 15:06:52.231952 - uniswap fully initiated
2025-09-08 15:06:52.232952 - check_balance...
2025-09-08 15:06:52.233952 - eth_balance...
2025-09-08 15:06:53.104013 - weth_balance...
2025-09-08 15:06:53.770442 - dai_balance...
2025-09-08 15:06:54.584357 - wbtc_balance...
2025-09-08 15:06:55.242874 - wsol_balance...
2025-09-08 15:06:55.880510 - usdc_balance...
2025-09-08 15:06:56.516160 - usdt_balance...
2025-09-08 15:08:08.080070 - initiating W3...
2025-09-08 15:08:08.097501 - uniswap fully initiated
2025-09-08 15:08:08.098442 - check_balance...
2025-09-08 15:08:08.099461 - eth_balance...
2025-09-08 15:08:09.391398 - weth_balance...
2025-09-08 15:08:10.083167 - dai_balance...
2025-09-08 15:08:10.722928 - wbtc_balance...
2025-09-08 15:08:11.368642 - wsol_balance...
2025-09-08 15:08:12.005837 - usdc_balance...
2025-09-08 15:08:12.640769 - usdt_balance...
2025-09-08 15:09:10.178473 - initiating W3...
2025-09-08 15:09:10.194484 - uniswap fully initiated
2025-09-08 15:09:10.195484 - check_balance...
2025-09-08 15:09:10.196485 - eth_balance...
2025-09-08 15:09:11.148022 - weth_balance...
2025-09-08 15:09:11.813022 - dai_balance...
2025-09-08 15:09:12.466240 - wbtc_balance...
2025-09-08 15:09:13.103589 - wsol_balance...
2025-09-08 15:09:13.746371 - usdc_balance...
2025-09-08 15:09:14.403073 - usdt_balance...
2025-09-08 15:10:01.155977 - initiating W3...
2025-09-08 15:10:01.173660 - uniswap fully initiated
2025-09-08 15:10:01.174659 - check_balance...
2025-09-08 15:10:01.175659 - eth_balance...
2025-09-08 15:10:02.013374 - weth_balance...
2025-09-08 15:10:02.667191 - dai_balance...
2025-09-08 15:10:03.315222 - wbtc_balance...
2025-09-08 15:10:03.998642 - wsol_balance...
2025-09-08 15:10:04.642926 - usdc_balance...
2025-09-08 15:10:05.373097 - usdt_balance...
2025-09-08 16:36:38.991997 - initiating W3...
2025-09-08 16:36:39.013088 - uniswap fully initiated
2025-09-08 16:36:39.015099 - check_balance...
2025-09-08 16:36:39.016086 - eth_balance...
2025-09-08 16:36:40.023123 - weth_balance...
2025-09-08 16:36:40.700889 - dai_balance...
2025-09-08 16:36:41.377967 - wbtc_balance...
2025-09-08 16:36:42.014462 - wsol_balance...
2025-09-08 16:36:42.656024 - usdc_balance...
2025-09-08 16:36:43.314564 - usdt_balance...
2025-09-08 16:36:59.097923 - initiating W3...
2025-09-08 16:36:59.115994 - uniswap fully initiated
2025-09-08 16:36:59.123562 - check_balance...
2025-09-08 16:36:59.124573 - eth_balance...
2025-09-08 16:37:00.251063 - weth_balance...
2025-09-08 16:37:00.902204 - dai_balance...
2025-09-08 16:37:01.562000 - wbtc_balance...
2025-09-08 16:37:02.208404 - wsol_balance...
2025-09-08 16:37:03.088043 - usdc_balance...
2025-09-08 16:37:03.729193 - usdt_balance...
2025-09-08 16:42:06.905741 - initiating W3...
2025-09-08 16:42:06.926387 - uniswap fully initiated
2025-09-08 16:42:06.928388 - check_balance...
2025-09-08 16:42:06.929389 - eth_balance...
2025-09-08 16:42:08.279315 - weth_balance...
2025-09-08 16:42:08.923715 - dai_balance...
2025-09-08 16:42:09.584153 - wbtc_balance...
2025-09-08 16:42:10.245793 - wsol_balance...
2025-09-08 16:42:10.907190 - usdc_balance...
2025-09-08 16:42:11.622608 - usdt_balance...
2025-09-08 16:48:34.763920 - initiating W3...
2025-09-08 16:48:34.788141 - uniswap fully initiated
2025-09-08 16:48:34.789619 - check_balance...
2025-09-08 16:48:34.791106 - eth_balance...
2025-09-08 16:48:35.724345 - weth_balance...
2025-09-08 16:48:36.368185 - dai_balance...
2025-09-08 16:48:37.006852 - wbtc_balance...
2025-09-08 16:48:37.647347 - wsol_balance...
2025-09-08 16:48:38.306394 - usdc_balance...
2025-09-08 16:48:39.318679 - usdt_balance...
2025-09-08 16:49:23.198336 - initiating W3...
2025-09-08 16:49:23.215944 - uniswap fully initiated
2025-09-08 16:49:23.216941 - check_balance...
2025-09-08 16:49:23.217944 - eth_balance...
2025-09-08 16:49:24.048152 - weth_balance...
2025-09-08 16:49:24.914233 - dai_balance...
2025-09-08 16:49:25.572635 - wbtc_balance...
2025-09-08 16:49:26.284262 - wsol_balance...
2025-09-08 16:49:26.935790 - usdc_balance...
2025-09-08 16:49:27.575427 - usdt_balance...
2025-09-08 16:51:00.466170 - --------> XXxXX pulses are being blocked.
2025-09-08 16:51:07.601193 - --------> XXxXX pulses are being blocked.
2025-09-08 16:51:11.665694 - --------> XXxXX pulses are being blocked.
2025-09-08 16:51:17.727315 - --------> XXxXX pulses are being blocked.
2025-09-08 16:51:21.812158 - --------> XXxXX pulses are being blocked.
2025-09-08 16:51:25.861334 - --------> XXxXX pulses are being blocked.
2025-09-08 16:51:29.952472 - --------> XXxXX pulses are being blocked.
2025-09-08 16:51:33.997914 - --------> XXxXX pulses are being blocked.
2025-09-08 16:51:38.082260 - --------> XXxXX pulses are being blocked.
2025-09-08 16:51:42.177484 - --------> XXxXX pulses are being blocked.
2025-09-08 16:51:46.244081 - --------> XXxXX pulses are being blocked.
2025-09-08 16:51:50.307383 - --------> XXxXX pulses are being blocked.
2025-09-08 16:51:54.406073 - --------> XXxXX pulses are being blocked.
2025-09-08 16:51:58.478494 - --------> XXxXX pulses are being blocked.
2025-09-08 16:52:02.536495 - --------> XXxXX pulses are being blocked.
2025-09-08 16:52:06.614873 - --------> XXxXX pulses are being blocked.
2025-09-08 16:52:10.674877 - --------> XXxXX pulses are being blocked.
2025-09-08 16:52:14.733574 - --------> XXxXX pulses are being blocked.
2025-09-08 16:52:18.791026 - --------> XXxXX pulses are being blocked.
2025-09-08 16:52:22.850134 - --------> XXxXX pulses are being blocked.
2025-09-08 16:52:26.907619 - --------> XXxXX pulses are being blocked.
2025-09-08 16:52:31.007374 - --------> XXxXX pulses are being blocked.
2025-09-08 16:52:35.103130 - --------> XXxXX pulses are being blocked.
2025-09-08 16:52:39.148154 - --------> XXxXX pulses are being blocked.
2025-09-08 16:52:43.219252 - --------> XXxXX pulses are being blocked.
2025-09-08 16:52:47.297546 - --------> XXxXX pulses are being blocked.
2025-09-08 16:52:51.387685 - --------> XXxXX pulses are being blocked.
2025-09-08 16:52:55.555826 - --------> XXxXX pulses are being blocked.
2025-09-08 16:52:59.614228 - --------> XXxXX pulses are being blocked.
2025-09-08 16:53:03.671576 - --------> XXxXX pulses are being blocked.
2025-09-08 16:53:07.738430 - --------> XXxXX pulses are being blocked.
2025-09-08 16:53:11.813041 - --------> XXxXX pulses are being blocked.
2025-09-08 16:53:15.880149 - --------> XXxXX pulses are being blocked.
2025-09-08 16:53:19.942376 - --------> XXxXX pulses are being blocked.
2025-09-08 16:53:23.986041 - --------> XXxXX pulses are being blocked.
2025-09-08 16:53:28.030238 - --------> XXxXX pulses are being blocked.
2025-09-08 16:53:32.108232 - --------> XXxXX pulses are being blocked.
2025-09-08 16:53:36.166648 - --------> XXxXX pulses are being blocked.
2025-09-08 16:53:40.235264 - --------> XXxXX pulses are being blocked.
2025-09-08 16:53:44.322154 - --------> XXxXX pulses are being blocked.
2025-09-08 16:53:48.375767 - --------> XXxXX pulses are being blocked.
2025-09-08 16:53:52.445244 - --------> XXxXX pulses are being blocked.
2025-09-08 16:53:56.519987 - --------> XXxXX pulses are being blocked.
2025-09-08 16:54:00.605019 - --------> XXxXX pulses are being blocked.
2025-09-08 16:54:04.692686 - --------> XXxXX pulses are being blocked.
2025-09-08 16:54:08.753621 - --------> XXxXX pulses are being blocked.
2025-09-08 16:54:12.814272 - --------> XXxXX pulses are being blocked.
2025-09-08 16:54:16.859360 - --------> XXxXX pulses are being blocked.
2025-09-08 16:54:20.917470 - --------> XXxXX pulses are being blocked.
2025-09-08 16:54:24.983013 - --------> XXxXX pulses are being blocked.
2025-09-08 16:54:29.044406 - --------> XXxXX pulses are being blocked.
2025-09-08 16:54:33.123576 - --------> XXxXX pulses are being blocked.
2025-09-08 16:54:37.206111 - --------> XXxXX pulses are being blocked.
2025-09-08 16:54:41.272206 - --------> XXxXX pulses are being blocked.
2025-09-08 16:54:45.353950 - --------> XXxXX pulses are being blocked.
2025-09-08 16:54:49.441096 - --------> XXxXX pulses are being blocked.
2025-09-08 16:54:53.503066 - --------> XXxXX pulses are being blocked.
2025-09-08 16:54:57.583125 - --------> XXxXX pulses are being blocked.
2025-09-08 16:55:01.641410 - --------> XXxXX pulses are being blocked.
2025-09-08 16:55:05.698218 - --------> XXxXX pulses are being blocked.
2025-09-08 16:55:09.888578 - --------> XXxXX pulses are being blocked.
2025-09-08 16:55:13.947977 - --------> XXxXX pulses are being blocked.
2025-09-08 16:55:18.013475 - --------> XXxXX pulses are being blocked.
2025-09-08 16:55:22.060218 - --------> XXxXX pulses are being blocked.
2025-09-08 16:55:26.151080 - --------> XXxXX pulses are being blocked.
2025-09-08 16:55:30.196304 - --------> XXxXX pulses are being blocked.
2025-09-08 16:55:34.281964 - --------> XXxXX pulses are being blocked.
2025-09-08 16:55:38.327412 - --------> XXxXX pulses are being blocked.
2025-09-08 16:55:42.375579 - --------> XXxXX pulses are being blocked.
2025-09-08 16:55:46.433921 - --------> XXxXX pulses are being blocked.
2025-09-08 16:55:50.480106 - --------> XXxXX pulses are being blocked.
2025-09-08 16:55:54.537043 - --------> XXxXX pulses are being blocked.
2025-09-08 16:55:58.600378 - --------> XXxXX pulses are being blocked.
2025-09-08 16:56:02.647140 - --------> XXxXX pulses are being blocked.
2025-09-08 16:56:06.712283 - --------> XXxXX pulses are being blocked.
2025-09-08 16:56:10.769915 - --------> XXxXX pulses are being blocked.
2025-09-08 16:56:14.832650 - --------> XXxXX pulses are being blocked.
2025-09-08 16:56:18.899321 - --------> XXxXX pulses are being blocked.
2025-09-08 16:56:22.947504 - --------> XXxXX pulses are being blocked.
2025-09-08 16:56:27.026011 - --------> XXxXX pulses are being blocked.
2025-09-08 16:56:31.125558 - --------> XXxXX pulses are being blocked.
2025-09-08 16:56:35.188714 - --------> XXxXX pulses are being blocked.
2025-09-08 16:56:39.261320 - --------> XXxXX pulses are being blocked.
2025-09-08 16:56:43.316517 - --------> XXxXX pulses are being blocked.
2025-09-08 16:56:47.413701 - --------> XXxXX pulses are being blocked.
2025-09-08 16:56:51.475262 - --------> XXxXX pulses are being blocked.
2025-09-08 16:56:55.547418 - --------> XXxXX pulses are being blocked.
2025-09-08 16:56:59.630310 - --------> XXxXX pulses are being blocked.
2025-09-08 16:57:03.702323 - --------> XXxXX pulses are being blocked.
2025-09-08 16:57:07.788496 - --------> XXxXX pulses are being blocked.
2025-09-08 16:57:11.832940 - --------> XXxXX pulses are being blocked.
2025-09-08 21:09:15.492758 - initiating W3...
2025-09-08 21:09:15.545659 - uniswap fully initiated
2025-09-08 21:09:15.546656 - check_balance...
2025-09-08 21:09:15.547654 - eth_balance...
2025-09-08 21:09:16.473428 - weth_balance...
2025-09-08 21:09:17.144510 - dai_balance...
2025-09-08 21:09:17.795566 - wbtc_balance...
2025-09-08 21:09:18.451499 - wsol_balance...
2025-09-08 21:09:19.107505 - usdc_balance...
2025-09-08 21:09:19.767886 - usdt_balance...
2025-09-08 21:10:16.199349 - initiating W3...
2025-09-08 21:10:16.214814 - uniswap fully initiated
2025-09-08 21:10:16.217330 - performing V3 Quote
2025-09-08 21:10:17.532523 - quote: 0.39916393346380374
2025-09-08 21:10:17.534521 - performing V3 Quote
2025-09-08 21:10:18.166527 - quote: 0.39916393346380374
2025-09-08 21:10:18.180178 - slipage_to_fee: 0.001236463130192406
2025-09-08 21:10:18.183195 - performing fiat_to_token (usdc -> weth)     fiat_amount: 1730     V3
2025-09-08 21:10:18.184197 - <-> swapping 1730 usdc for 0.3996580959641463 weth -- fee_teir: 500
2025-09-08 21:10:18.187715 - building tx for action: exactInputSingle
2025-09-08 21:10:18.928410 - waiting for https://etherscan.io/tx/0x9eac73d3fe32fc2f65680416afb18abe6690a6f6d627c49a31c13005de333cb6 

2025-09-08 21:10:29.649205 - initiating W3...
2025-09-08 21:10:29.679786 - uniswap fully initiated
2025-09-08 21:10:29.682786 - performing V3 Quote
2025-09-08 21:10:30.941490 - quote: 0.39916410221206416
2025-09-08 21:10:30.946023 - performing V3 Quote
2025-09-08 21:10:31.584642 - quote: 0.39916410221206416
2025-09-08 21:10:31.588656 - slipage_to_fee: 0.0012683431959233317
2025-09-08 21:10:31.591658 - performing fiat_to_token (usdc -> weth)     fiat_amount: 1730.0     V3
2025-09-08 21:10:31.592656 - <-> swapping 1730.0 usdc for 0.39967102223372203 weth -- fee_teir: 500
2025-09-08 21:10:31.596168 - building tx for action: exactInputSingle
2025-09-08 21:10:32.444366 - waiting for https://etherscan.io/tx/0x509f9682d0f682549d3e4cbd1b507ebc8a276d4ac21b73ac162ebc308cc1aa32 

2025-09-08 21:10:49.159501 - ---------------> successful
2025-09-08 21:10:49.160495 - V3: got_weth: 0.39916410221206416
2025-09-08 21:12:06.828179 - initiating W3...
2025-09-08 21:12:06.845695 - uniswap fully initiated
2025-09-08 21:12:06.847202 - check_balance...
2025-09-08 21:12:06.848210 - eth_balance...
2025-09-08 21:12:07.817549 - weth_balance...
2025-09-08 21:12:08.478742 - dai_balance...
2025-09-08 21:12:09.163785 - wbtc_balance...
2025-09-08 21:12:09.833606 - wsol_balance...
2025-09-08 21:12:10.510101 - usdc_balance...
2025-09-08 21:12:11.185361 - usdt_balance...
2025-09-08 21:12:32.647600 - Traceback (most recent call last):
  File "C:\Users\user\Desktop\p312\Lib\site-packages\web3\eth\eth.py", line 508, in wait_for_transaction_receipt
    _timeout.sleep(poll_latency)
  File "C:\Users\user\Desktop\p312\Lib\site-packages\web3\_utils\threads.py", line 101, in sleep
    self.check()
  File "C:\Users\user\Desktop\p312\Lib\site-packages\web3\_utils\threads.py", line 94, in check
    raise self
web3._utils.threads.Timeout: 120 seconds

During handling of the above exception, another exception occurred:

Traceback (most recent call last):
  File "C:\Users\user\Desktop\trade\dashboard\modules\uniswap\v3_class.py", line 1024, in build_and_execute_tx
    receipt = self.w3.eth.wait_for_transaction_receipt(tx_hash)
              ^^^^^^^^^^^^^^^^^^^^^^^^^^^^^^^^^^^^^^^^^^^^^^^^^
  File "C:\Users\user\Desktop\p312\Lib\site-packages\web3\eth\eth.py", line 512, in wait_for_transaction_receipt
    raise TimeExhausted(
web3.exceptions.TimeExhausted: Transaction HexBytes('0x509f9682d0f682549d3e4cbd1b507ebc8a276d4ac21b73ac162ebc308cc1aa32') is not in the chain after 120 seconds

2025-09-08 21:12:40.956801 - initiating W3...
2025-09-08 21:12:40.974467 - uniswap fully initiated
2025-09-08 21:12:40.975466 - check_balance...
2025-09-08 21:12:40.976465 - eth_balance...
2025-09-08 21:12:41.931515 - weth_balance...
2025-09-08 21:12:42.578466 - dai_balance...
2025-09-08 21:12:43.230963 - wbtc_balance...
2025-09-08 21:12:43.880797 - wsol_balance...
2025-09-08 21:12:44.543491 - usdc_balance...
2025-09-08 21:12:45.209773 - usdt_balance...
2025-09-08 21:18:30.920516 - initiating W3...
2025-09-08 21:18:30.940517 - uniswap fully initiated
2025-09-08 21:18:30.942553 - check_balance...
2025-09-08 21:18:30.943516 - eth_balance...
2025-09-08 21:18:31.824410 - weth_balance...
2025-09-08 21:18:32.475108 - dai_balance...
2025-09-08 21:18:33.097433 - wbtc_balance...
2025-09-08 21:18:33.733213 - wsol_balance...
2025-09-08 21:18:34.360120 - usdc_balance...
2025-09-08 21:18:35.393173 - usdt_balance...
2025-09-09 08:15:30.635906 - initiating W3...
2025-09-09 08:15:30.655903 - uniswap fully initiated
2025-09-09 08:15:30.656906 - performing V3 Quote
2025-09-09 08:15:32.059942 - quote: 0.000232118139135455
2025-09-09 08:15:32.063938 - performing V3 Quote
2025-09-09 08:15:32.723610 - quote: 0.000232118139135455
2025-09-09 08:15:32.725577 - performing V3 Quote
2025-09-09 08:15:33.369373 - quote: 0.000232118139135455
2025-09-09 08:15:33.385360 - slipage_to_fee: 0.0010331646027424426
2025-09-09 08:15:33.390354 - performing fiat_to_token (usdc -> weth)     fiat_amount: 1     V3
2025-09-09 08:15:33.391353 - <-> swapping 1 usdc for 0.00023235820340637128 weth -- fee_teir: 500
2025-09-09 08:15:33.395355 - building tx for action: exactInputSingle
2025-09-09 08:15:34.151634 - waiting for https://etherscan.io/tx/0x1cac5164a337ee962c55ea22adb5e7bfe815efd09edf04e861b859fbdb611633 

2025-09-09 08:16:12.870052 - -------------> failed
2025-09-09 08:17:58.276389 - initiating W3...
2025-09-09 08:17:58.292644 - uniswap fully initiated
2025-09-09 08:17:58.294617 - performing V3 Quote
2025-09-09 08:17:59.657473 - quote: 9.987709
2025-09-09 08:17:59.662481 - performing V3 Quote
2025-09-09 08:18:00.328507 - quote: 9.987709
2025-09-09 08:18:00.329506 - performing V3 Quote
2025-09-09 08:18:00.972613 - quote: 9.987709
2025-09-09 08:18:00.974579 - slipage_to_fee: 0.000887492183370794
2025-09-09 08:18:00.977590 - performing token_to_fiat: 0.0023195753 of weth -> usdc
2025-09-09 08:18:00.979583 - V3 got_weth: 0.0023195753
2025-09-09 08:18:00.980595 - <-> swapping 0.0023195753 weth for 9.996580887398 usdc -- fee_teir: 500
2025-09-09 08:18:00.983582 - building tx for action: exactInputSingle
2025-09-09 08:18:01.738122 - waiting for https://etherscan.io/tx/0x4efa5c30f636a1165c72ace52a95ac7ecabedbc13069a32af5e56d178f7679bc 

2025-09-09 08:18:36.920556 - ---------------> successful
2025-09-09 08:24:37.281293 - initiating W3...
2025-09-09 08:24:37.298260 - uniswap fully initiated
2025-09-09 08:24:37.299259 - check_balance...
2025-09-09 08:24:37.300259 - eth_balance...
2025-09-09 08:24:38.237856 - weth_balance...
2025-09-09 08:24:38.914813 - dai_balance...
2025-09-09 08:24:39.567990 - wbtc_balance...
2025-09-09 08:24:40.206500 - wsol_balance...
2025-09-09 08:24:40.839016 - usdc_balance...
2025-09-09 08:24:41.746037 - usdt_balance...
2025-09-09 08:24:57.493068 - initiating W3...
2025-09-09 08:24:57.516048 - uniswap fully initiated
2025-09-09 08:24:57.519067 - performing V3 Quote
2025-09-09 08:24:58.770369 - quote: 1.000095
2025-09-09 08:24:58.772364 - performing V3 Quote
2025-09-09 08:24:59.448650 - quote: 1.000095
2025-09-09 08:24:59.449650 - performing V3 Quote
2025-09-09 08:25:00.075708 - quote: 1.000095
2025-09-09 08:25:00.088670 - slipage_to_fee: -1.4747372102218026e-05
2025-09-09 08:25:00.090669 - performing token_to_fiat: 0.00023195753 of weth -> usdc
2025-09-09 08:25:00.093672 - V3 got_weth: 0.00023195753
2025-09-09 08:25:00.095686 - <-> swapping 0.00023195753 weth for 1.0000802514443998 usdc -- fee_teir: 500
2025-09-09 08:25:00.098322 - building tx for action: exactInputSingle
2025-09-09 08:25:00.572568 - --------> XXxXX pulses are being blocked.
2025-09-09 08:25:00.832371 - waiting for https://etherscan.io/tx/0x63dab28e843450a63f60724dd48f22762c4004aa97b563d4f83edf5b543b2ca9 

2025-09-09 08:25:04.667499 - --------> XXxXX pulses are being blocked.
2025-09-09 08:25:08.760538 - --------> XXxXX pulses are being blocked.
2025-09-09 08:25:12.823643 - --------> XXxXX pulses are being blocked.
2025-09-09 08:25:16.899026 - --------> XXxXX pulses are being blocked.
2025-09-09 08:25:20.994408 - --------> XXxXX pulses are being blocked.
2025-09-09 08:25:25.075263 - --------> XXxXX pulses are being blocked.
2025-09-09 08:25:29.142866 - --------> XXxXX pulses are being blocked.
2025-09-09 08:25:33.186196 - --------> XXxXX pulses are being blocked.
2025-09-09 08:25:37.286715 - --------> XXxXX pulses are being blocked.
2025-09-09 08:25:38.918249 - ---------------> successful
2025-09-09 08:25:41.367368 - --------> XXxXX pulses are being blocked.
2025-09-09 08:25:45.422738 - --------> XXxXX pulses are being blocked.
2025-09-09 08:25:49.491716 - --------> XXxXX pulses are being blocked.
2025-09-09 08:25:53.267998 - initiating W3...
2025-09-09 08:25:53.284998 - uniswap fully initiated
2025-09-09 08:25:53.285999 - check_balance...
2025-09-09 08:25:53.286999 - eth_balance...
2025-09-09 08:25:53.571064 - --------> XXxXX pulses are being blocked.
2025-09-09 08:25:54.194451 - weth_balance...
2025-09-09 08:25:54.830659 - dai_balance...
2025-09-09 08:25:55.462554 - wbtc_balance...
2025-09-09 08:25:56.096333 - wsol_balance...
2025-09-09 08:25:56.722202 - usdc_balance...
2025-09-09 08:25:57.356637 - usdt_balance...
2025-09-09 08:25:57.615084 - --------> XXxXX pulses are being blocked.
2025-09-09 08:26:01.685154 - --------> XXxXX pulses are being blocked.
2025-09-09 08:26:05.762957 - --------> XXxXX pulses are being blocked.
2025-09-09 08:27:19.262500 - --------> XXxXX pulses are being blocked.
2025-09-09 08:27:23.376480 - --------> XXxXX pulses are being blocked.
2025-09-09 08:27:29.487069 - --------> XXxXX pulses are being blocked.
2025-09-09 08:27:33.551634 - --------> XXxXX pulses are being blocked.
2025-09-09 10:54:51.374844 - initiating W3...
2025-09-09 10:54:51.417877 - uniswap fully initiated
2025-09-09 10:54:51.419879 - performing V3 Quote
2025-09-09 10:54:52.784948 - quote: 1744.653358
2025-09-09 10:54:52.785948 - performing V3 Quote
2025-09-09 10:54:53.440618 - quote: 1744.653358
2025-09-09 10:54:53.444581 - performing V3 Quote
2025-09-09 10:54:54.087890 - quote: 1744.653358
2025-09-09 10:54:54.090889 - slipage_to_fee: 0.0005014494652149548
2025-09-09 10:54:54.091890 - performing token_to_fiat: 0.39916410221206416 of weth -> usdc
2025-09-09 10:54:54.093892 - V3 got_weth: 0.39916410221206416
2025-09-09 10:54:54.094891 - <-> swapping 0.39916410221206416 weth for 1745.528652409268 usdc -- fee_teir: 500
2025-09-09 10:54:54.096891 - building tx for action: exactInputSingle
2025-09-09 10:54:54.897014 - waiting for https://etherscan.io/tx/0xaadf006550d0ab195e84d64c2b610dcbc74a260628a4678c614ad59dfc274166 

2025-09-09 10:55:14.273179 - ---------------> successful
2025-09-09 10:55:50.583467 - initiating W3...
2025-09-09 10:55:50.598466 - uniswap fully initiated
2025-09-09 10:55:50.599482 - check_balance...
2025-09-09 10:55:50.600473 - eth_balance...
2025-09-09 10:55:51.505365 - weth_balance...
2025-09-09 10:55:52.158846 - dai_balance...
2025-09-09 10:55:52.787481 - wbtc_balance...
2025-09-09 10:55:53.410737 - wsol_balance...
2025-09-09 10:55:54.046616 - usdc_balance...
2025-09-09 10:55:54.667389 - usdt_balance...
2025-09-09 10:56:42.580289 - initiating W3...
2025-09-09 10:56:42.594288 - uniswap fully initiated
2025-09-09 10:56:42.597290 - performing V3 Quote
2025-09-09 10:56:43.959488 - quote: 1020.093273
2025-09-09 10:56:43.960489 - performing V3 Quote
2025-09-09 10:56:44.598711 - quote: 1020.093273
2025-09-09 10:56:44.600712 - performing V3 Quote
2025-09-09 10:56:45.235085 - quote: 1020.093273
2025-09-09 10:56:45.239014 - slipage_to_fee: 0.0008351949360891209
2025-09-09 10:56:45.241016 - performing token_to_fiat: 0.23335907700511938 of weth -> usdc
2025-09-09 10:56:45.244014 - V3 got_weth: 0.23335907700511938
2025-09-09 10:56:45.245027 - <-> swapping 0.23335907700511938 weth for 1020.9459618973973 usdc -- fee_teir: 500
2025-09-09 10:56:45.247011 - building tx for action: exactInputSingle
2025-09-09 10:56:45.983617 - waiting for https://etherscan.io/tx/0x504524063669ea77e52f1b80c0c50866e6d0b243486f075a2492f871e2d1c2ce 

2025-09-09 10:57:37.621145 - -------------> failed
2025-09-09 11:06:45.590029 - initiating W3...
2025-09-09 11:06:45.608028 - uniswap fully initiated
2025-09-09 11:06:45.610056 - performing V3 Quote
2025-09-09 11:06:47.050669 - quote: 1020.544859
2025-09-09 11:06:47.051667 - performing V3 Quote
2025-09-09 11:06:47.711728 - quote: 1020.544859
2025-09-09 11:06:47.715670 - performing V3 Quote
2025-09-09 11:06:48.375251 - quote: 1020.544859
2025-09-09 11:06:48.394182 - slipage_to_fee: -5.743779949793501e-05
2025-09-09 11:06:48.399181 - performing token_to_fiat: 0.23335907700511938 of weth -> usdc
2025-09-09 11:06:48.402168 - V3 got_weth: 0.23335907700511938
2025-09-09 11:06:48.404171 - <-> swapping 0.23335907700511938 weth for 1020.4862445156971 usdc -- fee_teir: 500
2025-09-09 11:06:48.407163 - building tx for action: exactInputSingle
2025-09-09 11:06:49.148879 - waiting for https://etherscan.io/tx/0x0466ccdd2b48e5e059d85452cb201b6987b9f1ff99b25dbcdb8e596c5240c3a9 

2025-09-09 11:07:37.478513 - -------------> failed
2025-09-09 11:08:44.850680 - initiating W3...
2025-09-09 11:08:44.866690 - uniswap fully initiated
2025-09-09 11:08:44.870679 - performing V3 Quote
2025-09-09 11:08:46.264655 - quote: 0.22861169278386004
2025-09-09 11:08:46.266649 - performing V3 Quote
2025-09-09 11:08:46.954147 - quote: 0.22861169278386004
2025-09-09 11:08:46.955110 - performing V3 Quote
2025-09-09 11:08:47.616400 - quote: 0.22861169278386004
2025-09-09 11:08:47.631653 - slipage_to_fee: 0.0011635085903256332
2025-09-09 11:08:47.634661 - performing V3 Quote
2025-09-09 11:08:48.308335 - quote: 1000.153603
2025-09-09 11:08:48.310296 - performing V3 Quote
2025-09-09 11:08:48.967034 - quote: 1000.153603
2025-09-09 11:08:48.968020 - performing V3 Quote
2025-09-09 11:08:49.639438 - quote: 1000.154637
2025-09-09 11:08:49.652437 - slipage_to_fee: -0.0001536029999999755
2025-09-09 11:11:47.697914 - initiating W3...
2025-09-09 11:11:47.715902 - uniswap fully initiated
2025-09-09 11:11:47.716902 - check_balance...
2025-09-09 11:11:47.718907 - eth_balance...
2025-09-09 11:11:48.633200 - weth_balance...
2025-09-09 11:11:49.310665 - dai_balance...
2025-09-09 11:11:49.963528 - wbtc_balance...
2025-09-09 11:11:50.626000 - wsol_balance...
2025-09-09 11:11:51.276509 - usdc_balance...
2025-09-09 11:11:51.915918 - usdt_balance...
2025-09-09 11:12:55.667705 - initiating W3...
2025-09-09 11:12:55.682703 - uniswap fully initiated
2025-09-09 11:12:55.684719 - performing V3 Quote
2025-09-09 11:12:56.998044 - quote: 1020.775502
2025-09-09 11:12:56.999031 - performing V3 Quote
2025-09-09 11:12:57.626196 - quote: 1020.775502
2025-09-09 11:12:57.627163 - performing V3 Quote
2025-09-09 11:12:58.258191 - quote: 1020.775502
2025-09-09 11:12:58.273004 - slipage_to_fee: 0.00020581184857908636
2025-09-09 11:12:58.275005 - performing token_to_fiat: 0.23335907700511938 of weth -> usdc
2025-09-09 11:12:58.277011 - V3 got_weth: 0.23335907700511938
2025-09-09 11:12:58.278018 - <-> swapping 0.23335907700511938 weth for 1020.9856329404881 usdc -- fee_teir: 500
2025-09-09 11:12:58.281014 - building tx for action: exactInputSingle
2025-09-09 11:12:59.014113 - waiting for https://etherscan.io/tx/0x26877fe6707c9bde8e3fb801e180420146c428f7697737caabd25bf2d7c67869 

2025-09-09 11:13:36.868756 - ---------------> successful
2025-09-09 11:33:54.764366 - initiating W3...
2025-09-09 11:33:54.782361 - uniswap fully initiated
2025-09-09 11:33:54.783363 - check_balance...
2025-09-09 11:33:54.784371 - eth_balance...
2025-09-09 11:33:55.819339 - weth_balance...
2025-09-09 11:33:56.625812 - dai_balance...
2025-09-09 11:33:57.313226 - wbtc_balance...
2025-09-09 11:33:57.992314 - wsol_balance...
2025-09-09 11:33:58.664809 - usdc_balance...
2025-09-09 11:33:59.330754 - usdt_balance...
2025-09-09 13:16:19.592172 - Traceback (most recent call last):
  File "C:\Users\user\Desktop\trade\dashboard\models\models_position.py", line 178, in evaluate
    if self.min_profit_exit_price < self.price:
       ^^^^^^^^^^^^^^^^^^^^^^^^^^^^^^^^^^^^^^^
TypeError: '<' not supported between instances of 'float' and 'NoneType'

During handling of the above exception, another exception occurred:

Traceback (most recent call last):
  File "C:\Users\user\Desktop\p312\Lib\site-packages\urllib3\connection.py", line 198, in _new_conn
    sock = connection.create_connection(
           ^^^^^^^^^^^^^^^^^^^^^^^^^^^^^
  File "C:\Users\user\Desktop\p312\Lib\site-packages\urllib3\util\connection.py", line 60, in create_connection
    for res in socket.getaddrinfo(host, port, family, socket.SOCK_STREAM):
               ^^^^^^^^^^^^^^^^^^^^^^^^^^^^^^^^^^^^^^^^^^^^^^^^^^^^^^^^^^
  File "C:\Users\user\AppData\Local\Programs\Python\Python312\Lib\socket.py", line 978, in getaddrinfo
    for res in _socket.getaddrinfo(host, port, family, type, proto, flags):
               ^^^^^^^^^^^^^^^^^^^^^^^^^^^^^^^^^^^^^^^^^^^^^^^^^^^^^^^^^^^
socket.gaierror: [Errno 11001] getaddrinfo failed

The above exception was the direct cause of the following exception:

Traceback (most recent call last):
  File "C:\Users\user\Desktop\p312\Lib\site-packages\urllib3\connectionpool.py", line 787, in urlopen
    response = self._make_request(
               ^^^^^^^^^^^^^^^^^^^
  File "C:\Users\user\Desktop\p312\Lib\site-packages\urllib3\connectionpool.py", line 488, in _make_request
    raise new_e
  File "C:\Users\user\Desktop\p312\Lib\site-packages\urllib3\connectionpool.py", line 464, in _make_request
    self._validate_conn(conn)
  File "C:\Users\user\Desktop\p312\Lib\site-packages\urllib3\connectionpool.py", line 1093, in _validate_conn
    conn.connect()
  File "C:\Users\user\Desktop\p312\Lib\site-packages\urllib3\connection.py", line 753, in connect
    self.sock = sock = self._new_conn()
                       ^^^^^^^^^^^^^^^^
  File "C:\Users\user\Desktop\p312\Lib\site-packages\urllib3\connection.py", line 205, in _new_conn
    raise NameResolutionError(self.host, self, e) from e
urllib3.exceptions.NameResolutionError: <urllib3.connection.HTTPSConnection object at 0x0000017CBB2D0710>: Failed to resolve 'api.telegram.org' ([Errno 11001] getaddrinfo failed)

The above exception was the direct cause of the following exception:

Traceback (most recent call last):
  File "C:\Users\user\Desktop\p312\Lib\site-packages\requests\adapters.py", line 667, in send
    resp = conn.urlopen(
           ^^^^^^^^^^^^^
  File "C:\Users\user\Desktop\p312\Lib\site-packages\urllib3\connectionpool.py", line 841, in urlopen
    retries = retries.increment(
              ^^^^^^^^^^^^^^^^^^
  File "C:\Users\user\Desktop\p312\Lib\site-packages\urllib3\util\retry.py", line 519, in increment
    raise MaxRetryError(_pool, url, reason) from reason  # type: ignore[arg-type]
    ^^^^^^^^^^^^^^^^^^^^^^^^^^^^^^^^^^^^^^^^^^^^^^^^^^^
urllib3.exceptions.MaxRetryError: HTTPSConnectionPool(host='api.telegram.org', port=443): Max retries exceeded with url: /bot8452876784:AAHzQeMZQGmEA8PcqXnGwdyh5y7dBYjiCwg/sendMessage?chat_id=5214991865&text=%3Cb%3Eruntime%20error%3C/b%3E%0A%0ATraceback%20(most%20recent%20call%20last):%0A%20%20File%20%22C:%5CUsers%5Cuser%5CDesktop%5Ctrade%5Cdashboard%5Cmodels%5Cmodels_position.py%22,%20line%20178,%20in%20evaluate%0A%20%20%20%20if%20self.min_profit_exit_price%20%3C%20self.price:%0A%20%20%20%20%20%20%20%5E%5E%5E%5E%5E%5E%5E%5E%5E%5E%5E%5E%5E%5E%5E%5E%5E%5E%5E%5E%5E%5E%5E%5E%5E%5E%5E%5E%5E%5E%5E%5E%5E%5E%5E%5E%5E%5E%5E%0ATypeError:%20'%3C'%20not%20supported%20between%20instances%20of%20'float'%20and%20'NoneType'%0A&parse_mode=HTML (Caused by NameResolutionError("<urllib3.connection.HTTPSConnection object at 0x0000017CBB2D0710>: Failed to resolve 'api.telegram.org' ([Errno 11001] getaddrinfo failed)"))

During handling of the above exception, another exception occurred:

Traceback (most recent call last):
  File "C:\Users\user\Desktop\trade\dashboard\modules\notification\notification.py", line 21, in send
    requests.get(url)
  File "C:\Users\user\Desktop\p312\Lib\site-packages\requests\api.py", line 73, in get
    return request("get", url, params=params, **kwargs)
           ^^^^^^^^^^^^^^^^^^^^^^^^^^^^^^^^^^^^^^^^^^^^
  File "C:\Users\user\Desktop\p312\Lib\site-packages\requests\api.py", line 59, in request
    return session.request(method=method, url=url, **kwargs)
           ^^^^^^^^^^^^^^^^^^^^^^^^^^^^^^^^^^^^^^^^^^^^^^^^^
  File "C:\Users\user\Desktop\p312\Lib\site-packages\requests\sessions.py", line 589, in request
    resp = self.send(prep, **send_kwargs)
           ^^^^^^^^^^^^^^^^^^^^^^^^^^^^^^
  File "C:\Users\user\Desktop\p312\Lib\site-packages\requests\sessions.py", line 703, in send
    r = adapter.send(request, **kwargs)
        ^^^^^^^^^^^^^^^^^^^^^^^^^^^^^^^
  File "C:\Users\user\Desktop\p312\Lib\site-packages\requests\adapters.py", line 700, in send
    raise ConnectionError(e, request=request)
requests.exceptions.ConnectionError: HTTPSConnectionPool(host='api.telegram.org', port=443): Max retries exceeded with url: /bot8452876784:AAHzQeMZQGmEA8PcqXnGwdyh5y7dBYjiCwg/sendMessage?chat_id=5214991865&text=%3Cb%3Eruntime%20error%3C/b%3E%0A%0ATraceback%20(most%20recent%20call%20last):%0A%20%20File%20%22C:%5CUsers%5Cuser%5CDesktop%5Ctrade%5Cdashboard%5Cmodels%5Cmodels_position.py%22,%20line%20178,%20in%20evaluate%0A%20%20%20%20if%20self.min_profit_exit_price%20%3C%20self.price:%0A%20%20%20%20%20%20%20%5E%5E%5E%5E%5E%5E%5E%5E%5E%5E%5E%5E%5E%5E%5E%5E%5E%5E%5E%5E%5E%5E%5E%5E%5E%5E%5E%5E%5E%5E%5E%5E%5E%5E%5E%5E%5E%5E%5E%0ATypeError:%20'%3C'%20not%20supported%20between%20instances%20of%20'float'%20and%20'NoneType'%0A&parse_mode=HTML (Caused by NameResolutionError("<urllib3.connection.HTTPSConnection object at 0x0000017CBB2D0710>: Failed to resolve 'api.telegram.org' ([Errno 11001] getaddrinfo failed)"))

2025-09-09 13:16:19.623763 - Traceback (most recent call last):
  File "C:\Users\user\Desktop\p312\Lib\site-packages\django\db\backends\utils.py", line 105, in _execute
    return self.cursor.execute(sql, params)
           ^^^^^^^^^^^^^^^^^^^^^^^^^^^^^^^^
psycopg2.errors.NotNullViolation: null value in column "price" of relation "dashboard_position" violates not-null constraint
DETAIL:  Failing row contains (37, 4281.44, 4375, 3000, 3000, d005aba4651f4d97a0b4ce6cece9d5a0, t, reaching_min_profit_exit_price, 0, f, 43.7, 598.6, null, 2037.16, 37.16, 1.86, 98.98, 85.03, 0, 1757085038, 1757409379, 0, t, 0.07, auto_exit_style_only_after_min_profit, 8, 0.46713208022382086).


The above exception was the direct cause of the following exception:

Traceback (most recent call last):
  File "C:\Users\user\Desktop\trade\dashboard\views_pages\pulse_handler.py", line 45, in handle_a_pulse
    position.save()
  File "C:\Users\user\Desktop\trade\dashboard\models\models_position.py", line 114, in save
    super(Position, self).save(*args, **kwargs)
  File "C:\Users\user\Desktop\p312\Lib\site-packages\django\db\models\base.py", line 902, in save
    self.save_base(
  File "C:\Users\user\Desktop\p312\Lib\site-packages\django\db\models\base.py", line 1008, in save_base
    updated = self._save_table(
              ^^^^^^^^^^^^^^^^^
  File "C:\Users\user\Desktop\p312\Lib\site-packages\django\db\models\base.py", line 1138, in _save_table
    updated = self._do_update(
              ^^^^^^^^^^^^^^^^
  File "C:\Users\user\Desktop\p312\Lib\site-packages\django\db\models\base.py", line 1203, in _do_update
    return filtered._update(values) > 0
           ^^^^^^^^^^^^^^^^^^^^^^^^
  File "C:\Users\user\Desktop\p312\Lib\site-packages\django\db\models\query.py", line 1286, in _update
    return query.get_compiler(self.db).execute_sql(ROW_COUNT)
           ^^^^^^^^^^^^^^^^^^^^^^^^^^^^^^^^^^^^^^^^^^^^^^^^^^
  File "C:\Users\user\Desktop\p312\Lib\site-packages\django\db\models\sql\compiler.py", line 2060, in execute_sql
    row_count = super().execute_sql(result_type)
                ^^^^^^^^^^^^^^^^^^^^^^^^^^^^^^^^
  File "C:\Users\user\Desktop\p312\Lib\site-packages\django\db\models\sql\compiler.py", line 1623, in execute_sql
    cursor.execute(sql, params)
  File "C:\Users\user\Desktop\p312\Lib\site-packages\django\db\backends\utils.py", line 122, in execute
    return super().execute(sql, params)
           ^^^^^^^^^^^^^^^^^^^^^^^^^^^^
  File "C:\Users\user\Desktop\p312\Lib\site-packages\django\db\backends\utils.py", line 79, in execute
    return self._execute_with_wrappers(
           ^^^^^^^^^^^^^^^^^^^^^^^^^^^^
  File "C:\Users\user\Desktop\p312\Lib\site-packages\django\db\backends\utils.py", line 92, in _execute_with_wrappers
    return executor(sql, params, many, context)
           ^^^^^^^^^^^^^^^^^^^^^^^^^^^^^^^^^^^^
  File "C:\Users\user\Desktop\p312\Lib\site-packages\django\db\backends\utils.py", line 100, in _execute
    with self.db.wrap_database_errors:
         ^^^^^^^^^^^^^^^^^^^^^^^^^^^^
  File "C:\Users\user\Desktop\p312\Lib\site-packages\django\db\utils.py", line 91, in __exit__
    raise dj_exc_value.with_traceback(traceback) from exc_value
  File "C:\Users\user\Desktop\p312\Lib\site-packages\django\db\backends\utils.py", line 105, in _execute
    return self.cursor.execute(sql, params)
           ^^^^^^^^^^^^^^^^^^^^^^^^^^^^^^^^
django.db.utils.IntegrityError: null value in column "price" of relation "dashboard_position" violates not-null constraint
DETAIL:  Failing row contains (37, 4281.44, 4375, 3000, 3000, d005aba4651f4d97a0b4ce6cece9d5a0, t, reaching_min_profit_exit_price, 0, f, 43.7, 598.6, null, 2037.16, 37.16, 1.86, 98.98, 85.03, 0, 1757085038, 1757409379, 0, t, 0.07, auto_exit_style_only_after_min_profit, 8, 0.46713208022382086).


2025-09-09 13:16:23.717416 - Traceback (most recent call last):
  File "C:\Users\user\Desktop\trade\dashboard\models\models_position.py", line 178, in evaluate
    if self.min_profit_exit_price < self.price:
       ^^^^^^^^^^^^^^^^^^^^^^^^^^^^^^^^^^^^^^^
TypeError: '<' not supported between instances of 'float' and 'NoneType'

During handling of the above exception, another exception occurred:

Traceback (most recent call last):
  File "C:\Users\user\Desktop\p312\Lib\site-packages\urllib3\connection.py", line 198, in _new_conn
    sock = connection.create_connection(
           ^^^^^^^^^^^^^^^^^^^^^^^^^^^^^
  File "C:\Users\user\Desktop\p312\Lib\site-packages\urllib3\util\connection.py", line 60, in create_connection
    for res in socket.getaddrinfo(host, port, family, socket.SOCK_STREAM):
               ^^^^^^^^^^^^^^^^^^^^^^^^^^^^^^^^^^^^^^^^^^^^^^^^^^^^^^^^^^
  File "C:\Users\user\AppData\Local\Programs\Python\Python312\Lib\socket.py", line 978, in getaddrinfo
    for res in _socket.getaddrinfo(host, port, family, type, proto, flags):
               ^^^^^^^^^^^^^^^^^^^^^^^^^^^^^^^^^^^^^^^^^^^^^^^^^^^^^^^^^^^
socket.gaierror: [Errno 11001] getaddrinfo failed

The above exception was the direct cause of the following exception:

Traceback (most recent call last):
  File "C:\Users\user\Desktop\p312\Lib\site-packages\urllib3\connectionpool.py", line 787, in urlopen
    response = self._make_request(
               ^^^^^^^^^^^^^^^^^^^
  File "C:\Users\user\Desktop\p312\Lib\site-packages\urllib3\connectionpool.py", line 488, in _make_request
    raise new_e
  File "C:\Users\user\Desktop\p312\Lib\site-packages\urllib3\connectionpool.py", line 464, in _make_request
    self._validate_conn(conn)
  File "C:\Users\user\Desktop\p312\Lib\site-packages\urllib3\connectionpool.py", line 1093, in _validate_conn
    conn.connect()
  File "C:\Users\user\Desktop\p312\Lib\site-packages\urllib3\connection.py", line 753, in connect
    self.sock = sock = self._new_conn()
                       ^^^^^^^^^^^^^^^^
  File "C:\Users\user\Desktop\p312\Lib\site-packages\urllib3\connection.py", line 205, in _new_conn
    raise NameResolutionError(self.host, self, e) from e
urllib3.exceptions.NameResolutionError: <urllib3.connection.HTTPSConnection object at 0x0000017CBB486B70>: Failed to resolve 'api.telegram.org' ([Errno 11001] getaddrinfo failed)

The above exception was the direct cause of the following exception:

Traceback (most recent call last):
  File "C:\Users\user\Desktop\p312\Lib\site-packages\requests\adapters.py", line 667, in send
    resp = conn.urlopen(
           ^^^^^^^^^^^^^
  File "C:\Users\user\Desktop\p312\Lib\site-packages\urllib3\connectionpool.py", line 841, in urlopen
    retries = retries.increment(
              ^^^^^^^^^^^^^^^^^^
  File "C:\Users\user\Desktop\p312\Lib\site-packages\urllib3\util\retry.py", line 519, in increment
    raise MaxRetryError(_pool, url, reason) from reason  # type: ignore[arg-type]
    ^^^^^^^^^^^^^^^^^^^^^^^^^^^^^^^^^^^^^^^^^^^^^^^^^^^
urllib3.exceptions.MaxRetryError: HTTPSConnectionPool(host='api.telegram.org', port=443): Max retries exceeded with url: /bot8452876784:AAHzQeMZQGmEA8PcqXnGwdyh5y7dBYjiCwg/sendMessage?chat_id=5214991865&text=%3Cb%3Eruntime%20error%3C/b%3E%0A%0ATraceback%20(most%20recent%20call%20last):%0A%20%20File%20%22C:%5CUsers%5Cuser%5CDesktop%5Ctrade%5Cdashboard%5Cmodels%5Cmodels_position.py%22,%20line%20178,%20in%20evaluate%0A%20%20%20%20if%20self.min_profit_exit_price%20%3C%20self.price:%0A%20%20%20%20%20%20%20%5E%5E%5E%5E%5E%5E%5E%5E%5E%5E%5E%5E%5E%5E%5E%5E%5E%5E%5E%5E%5E%5E%5E%5E%5E%5E%5E%5E%5E%5E%5E%5E%5E%5E%5E%5E%5E%5E%5E%0ATypeError:%20'%3C'%20not%20supported%20between%20instances%20of%20'float'%20and%20'NoneType'%0A&parse_mode=HTML (Caused by NameResolutionError("<urllib3.connection.HTTPSConnection object at 0x0000017CBB486B70>: Failed to resolve 'api.telegram.org' ([Errno 11001] getaddrinfo failed)"))

During handling of the above exception, another exception occurred:

Traceback (most recent call last):
  File "C:\Users\user\Desktop\trade\dashboard\modules\notification\notification.py", line 21, in send
    requests.get(url)
  File "C:\Users\user\Desktop\p312\Lib\site-packages\requests\api.py", line 73, in get
    return request("get", url, params=params, **kwargs)
           ^^^^^^^^^^^^^^^^^^^^^^^^^^^^^^^^^^^^^^^^^^^^
  File "C:\Users\user\Desktop\p312\Lib\site-packages\requests\api.py", line 59, in request
    return session.request(method=method, url=url, **kwargs)
           ^^^^^^^^^^^^^^^^^^^^^^^^^^^^^^^^^^^^^^^^^^^^^^^^^
  File "C:\Users\user\Desktop\p312\Lib\site-packages\requests\sessions.py", line 589, in request
    resp = self.send(prep, **send_kwargs)
           ^^^^^^^^^^^^^^^^^^^^^^^^^^^^^^
  File "C:\Users\user\Desktop\p312\Lib\site-packages\requests\sessions.py", line 703, in send
    r = adapter.send(request, **kwargs)
        ^^^^^^^^^^^^^^^^^^^^^^^^^^^^^^^
  File "C:\Users\user\Desktop\p312\Lib\site-packages\requests\adapters.py", line 700, in send
    raise ConnectionError(e, request=request)
requests.exceptions.ConnectionError: HTTPSConnectionPool(host='api.telegram.org', port=443): Max retries exceeded with url: /bot8452876784:AAHzQeMZQGmEA8PcqXnGwdyh5y7dBYjiCwg/sendMessage?chat_id=5214991865&text=%3Cb%3Eruntime%20error%3C/b%3E%0A%0ATraceback%20(most%20recent%20call%20last):%0A%20%20File%20%22C:%5CUsers%5Cuser%5CDesktop%5Ctrade%5Cdashboard%5Cmodels%5Cmodels_position.py%22,%20line%20178,%20in%20evaluate%0A%20%20%20%20if%20self.min_profit_exit_price%20%3C%20self.price:%0A%20%20%20%20%20%20%20%5E%5E%5E%5E%5E%5E%5E%5E%5E%5E%5E%5E%5E%5E%5E%5E%5E%5E%5E%5E%5E%5E%5E%5E%5E%5E%5E%5E%5E%5E%5E%5E%5E%5E%5E%5E%5E%5E%5E%0ATypeError:%20'%3C'%20not%20supported%20between%20instances%20of%20'float'%20and%20'NoneType'%0A&parse_mode=HTML (Caused by NameResolutionError("<urllib3.connection.HTTPSConnection object at 0x0000017CBB486B70>: Failed to resolve 'api.telegram.org' ([Errno 11001] getaddrinfo failed)"))

2025-09-09 13:16:23.723934 - Traceback (most recent call last):
  File "C:\Users\user\Desktop\p312\Lib\site-packages\django\db\backends\utils.py", line 105, in _execute
    return self.cursor.execute(sql, params)
           ^^^^^^^^^^^^^^^^^^^^^^^^^^^^^^^^
psycopg2.errors.NotNullViolation: null value in column "price" of relation "dashboard_position" violates not-null constraint
DETAIL:  Failing row contains (37, 4281.44, 4375, 3000, 3000, d005aba4651f4d97a0b4ce6cece9d5a0, t, reaching_min_profit_exit_price, 0, f, 43.7, 598.6, null, 2037.16, 37.16, 1.86, 98.98, 85.03, 0, 1757085038, 1757409383, 0, t, 0.07, auto_exit_style_only_after_min_profit, 8, 0.46713208022382086).


The above exception was the direct cause of the following exception:

Traceback (most recent call last):
  File "C:\Users\user\Desktop\trade\dashboard\views_pages\pulse_handler.py", line 45, in handle_a_pulse
    position.save()
  File "C:\Users\user\Desktop\trade\dashboard\models\models_position.py", line 114, in save
    super(Position, self).save(*args, **kwargs)
  File "C:\Users\user\Desktop\p312\Lib\site-packages\django\db\models\base.py", line 902, in save
    self.save_base(
  File "C:\Users\user\Desktop\p312\Lib\site-packages\django\db\models\base.py", line 1008, in save_base
    updated = self._save_table(
              ^^^^^^^^^^^^^^^^^
  File "C:\Users\user\Desktop\p312\Lib\site-packages\django\db\models\base.py", line 1138, in _save_table
    updated = self._do_update(
              ^^^^^^^^^^^^^^^^
  File "C:\Users\user\Desktop\p312\Lib\site-packages\django\db\models\base.py", line 1203, in _do_update
    return filtered._update(values) > 0
           ^^^^^^^^^^^^^^^^^^^^^^^^
  File "C:\Users\user\Desktop\p312\Lib\site-packages\django\db\models\query.py", line 1286, in _update
    return query.get_compiler(self.db).execute_sql(ROW_COUNT)
           ^^^^^^^^^^^^^^^^^^^^^^^^^^^^^^^^^^^^^^^^^^^^^^^^^^
  File "C:\Users\user\Desktop\p312\Lib\site-packages\django\db\models\sql\compiler.py", line 2060, in execute_sql
    row_count = super().execute_sql(result_type)
                ^^^^^^^^^^^^^^^^^^^^^^^^^^^^^^^^
  File "C:\Users\user\Desktop\p312\Lib\site-packages\django\db\models\sql\compiler.py", line 1623, in execute_sql
    cursor.execute(sql, params)
  File "C:\Users\user\Desktop\p312\Lib\site-packages\django\db\backends\utils.py", line 122, in execute
    return super().execute(sql, params)
           ^^^^^^^^^^^^^^^^^^^^^^^^^^^^
  File "C:\Users\user\Desktop\p312\Lib\site-packages\django\db\backends\utils.py", line 79, in execute
    return self._execute_with_wrappers(
           ^^^^^^^^^^^^^^^^^^^^^^^^^^^^
  File "C:\Users\user\Desktop\p312\Lib\site-packages\django\db\backends\utils.py", line 92, in _execute_with_wrappers
    return executor(sql, params, many, context)
           ^^^^^^^^^^^^^^^^^^^^^^^^^^^^^^^^^^^^
  File "C:\Users\user\Desktop\p312\Lib\site-packages\django\db\backends\utils.py", line 100, in _execute
    with self.db.wrap_database_errors:
         ^^^^^^^^^^^^^^^^^^^^^^^^^^^^
  File "C:\Users\user\Desktop\p312\Lib\site-packages\django\db\utils.py", line 91, in __exit__
    raise dj_exc_value.with_traceback(traceback) from exc_value
  File "C:\Users\user\Desktop\p312\Lib\site-packages\django\db\backends\utils.py", line 105, in _execute
    return self.cursor.execute(sql, params)
           ^^^^^^^^^^^^^^^^^^^^^^^^^^^^^^^^
django.db.utils.IntegrityError: null value in column "price" of relation "dashboard_position" violates not-null constraint
DETAIL:  Failing row contains (37, 4281.44, 4375, 3000, 3000, d005aba4651f4d97a0b4ce6cece9d5a0, t, reaching_min_profit_exit_price, 0, f, 43.7, 598.6, null, 2037.16, 37.16, 1.86, 98.98, 85.03, 0, 1757085038, 1757409383, 0, t, 0.07, auto_exit_style_only_after_min_profit, 8, 0.46713208022382086).


2025-09-09 13:16:27.814741 - Traceback (most recent call last):
  File "C:\Users\user\Desktop\trade\dashboard\models\models_position.py", line 178, in evaluate
    if self.min_profit_exit_price < self.price:
       ^^^^^^^^^^^^^^^^^^^^^^^^^^^^^^^^^^^^^^^
TypeError: '<' not supported between instances of 'float' and 'NoneType'

During handling of the above exception, another exception occurred:

Traceback (most recent call last):
  File "C:\Users\user\Desktop\p312\Lib\site-packages\urllib3\connection.py", line 198, in _new_conn
    sock = connection.create_connection(
           ^^^^^^^^^^^^^^^^^^^^^^^^^^^^^
  File "C:\Users\user\Desktop\p312\Lib\site-packages\urllib3\util\connection.py", line 60, in create_connection
    for res in socket.getaddrinfo(host, port, family, socket.SOCK_STREAM):
               ^^^^^^^^^^^^^^^^^^^^^^^^^^^^^^^^^^^^^^^^^^^^^^^^^^^^^^^^^^
  File "C:\Users\user\AppData\Local\Programs\Python\Python312\Lib\socket.py", line 978, in getaddrinfo
    for res in _socket.getaddrinfo(host, port, family, type, proto, flags):
               ^^^^^^^^^^^^^^^^^^^^^^^^^^^^^^^^^^^^^^^^^^^^^^^^^^^^^^^^^^^
socket.gaierror: [Errno 11001] getaddrinfo failed

The above exception was the direct cause of the following exception:

Traceback (most recent call last):
  File "C:\Users\user\Desktop\p312\Lib\site-packages\urllib3\connectionpool.py", line 787, in urlopen
    response = self._make_request(
               ^^^^^^^^^^^^^^^^^^^
  File "C:\Users\user\Desktop\p312\Lib\site-packages\urllib3\connectionpool.py", line 488, in _make_request
    raise new_e
  File "C:\Users\user\Desktop\p312\Lib\site-packages\urllib3\connectionpool.py", line 464, in _make_request
    self._validate_conn(conn)
  File "C:\Users\user\Desktop\p312\Lib\site-packages\urllib3\connectionpool.py", line 1093, in _validate_conn
    conn.connect()
  File "C:\Users\user\Desktop\p312\Lib\site-packages\urllib3\connection.py", line 753, in connect
    self.sock = sock = self._new_conn()
                       ^^^^^^^^^^^^^^^^
  File "C:\Users\user\Desktop\p312\Lib\site-packages\urllib3\connection.py", line 205, in _new_conn
    raise NameResolutionError(self.host, self, e) from e
urllib3.exceptions.NameResolutionError: <urllib3.connection.HTTPSConnection object at 0x0000017CBC5F6600>: Failed to resolve 'api.telegram.org' ([Errno 11001] getaddrinfo failed)

The above exception was the direct cause of the following exception:

Traceback (most recent call last):
  File "C:\Users\user\Desktop\p312\Lib\site-packages\requests\adapters.py", line 667, in send
    resp = conn.urlopen(
           ^^^^^^^^^^^^^
  File "C:\Users\user\Desktop\p312\Lib\site-packages\urllib3\connectionpool.py", line 841, in urlopen
    retries = retries.increment(
              ^^^^^^^^^^^^^^^^^^
  File "C:\Users\user\Desktop\p312\Lib\site-packages\urllib3\util\retry.py", line 519, in increment
    raise MaxRetryError(_pool, url, reason) from reason  # type: ignore[arg-type]
    ^^^^^^^^^^^^^^^^^^^^^^^^^^^^^^^^^^^^^^^^^^^^^^^^^^^
urllib3.exceptions.MaxRetryError: HTTPSConnectionPool(host='api.telegram.org', port=443): Max retries exceeded with url: /bot8452876784:AAHzQeMZQGmEA8PcqXnGwdyh5y7dBYjiCwg/sendMessage?chat_id=5214991865&text=%3Cb%3Eruntime%20error%3C/b%3E%0A%0ATraceback%20(most%20recent%20call%20last):%0A%20%20File%20%22C:%5CUsers%5Cuser%5CDesktop%5Ctrade%5Cdashboard%5Cmodels%5Cmodels_position.py%22,%20line%20178,%20in%20evaluate%0A%20%20%20%20if%20self.min_profit_exit_price%20%3C%20self.price:%0A%20%20%20%20%20%20%20%5E%5E%5E%5E%5E%5E%5E%5E%5E%5E%5E%5E%5E%5E%5E%5E%5E%5E%5E%5E%5E%5E%5E%5E%5E%5E%5E%5E%5E%5E%5E%5E%5E%5E%5E%5E%5E%5E%5E%0ATypeError:%20'%3C'%20not%20supported%20between%20instances%20of%20'float'%20and%20'NoneType'%0A&parse_mode=HTML (Caused by NameResolutionError("<urllib3.connection.HTTPSConnection object at 0x0000017CBC5F6600>: Failed to resolve 'api.telegram.org' ([Errno 11001] getaddrinfo failed)"))

During handling of the above exception, another exception occurred:

Traceback (most recent call last):
  File "C:\Users\user\Desktop\trade\dashboard\modules\notification\notification.py", line 21, in send
    requests.get(url)
  File "C:\Users\user\Desktop\p312\Lib\site-packages\requests\api.py", line 73, in get
    return request("get", url, params=params, **kwargs)
           ^^^^^^^^^^^^^^^^^^^^^^^^^^^^^^^^^^^^^^^^^^^^
  File "C:\Users\user\Desktop\p312\Lib\site-packages\requests\api.py", line 59, in request
    return session.request(method=method, url=url, **kwargs)
           ^^^^^^^^^^^^^^^^^^^^^^^^^^^^^^^^^^^^^^^^^^^^^^^^^
  File "C:\Users\user\Desktop\p312\Lib\site-packages\requests\sessions.py", line 589, in request
    resp = self.send(prep, **send_kwargs)
           ^^^^^^^^^^^^^^^^^^^^^^^^^^^^^^
  File "C:\Users\user\Desktop\p312\Lib\site-packages\requests\sessions.py", line 703, in send
    r = adapter.send(request, **kwargs)
        ^^^^^^^^^^^^^^^^^^^^^^^^^^^^^^^
  File "C:\Users\user\Desktop\p312\Lib\site-packages\requests\adapters.py", line 700, in send
    raise ConnectionError(e, request=request)
requests.exceptions.ConnectionError: HTTPSConnectionPool(host='api.telegram.org', port=443): Max retries exceeded with url: /bot8452876784:AAHzQeMZQGmEA8PcqXnGwdyh5y7dBYjiCwg/sendMessage?chat_id=5214991865&text=%3Cb%3Eruntime%20error%3C/b%3E%0A%0ATraceback%20(most%20recent%20call%20last):%0A%20%20File%20%22C:%5CUsers%5Cuser%5CDesktop%5Ctrade%5Cdashboard%5Cmodels%5Cmodels_position.py%22,%20line%20178,%20in%20evaluate%0A%20%20%20%20if%20self.min_profit_exit_price%20%3C%20self.price:%0A%20%20%20%20%20%20%20%5E%5E%5E%5E%5E%5E%5E%5E%5E%5E%5E%5E%5E%5E%5E%5E%5E%5E%5E%5E%5E%5E%5E%5E%5E%5E%5E%5E%5E%5E%5E%5E%5E%5E%5E%5E%5E%5E%5E%0ATypeError:%20'%3C'%20not%20supported%20between%20instances%20of%20'float'%20and%20'NoneType'%0A&parse_mode=HTML (Caused by NameResolutionError("<urllib3.connection.HTTPSConnection object at 0x0000017CBC5F6600>: Failed to resolve 'api.telegram.org' ([Errno 11001] getaddrinfo failed)"))

2025-09-09 13:16:27.832742 - Traceback (most recent call last):
  File "C:\Users\user\Desktop\p312\Lib\site-packages\django\db\backends\utils.py", line 105, in _execute
    return self.cursor.execute(sql, params)
           ^^^^^^^^^^^^^^^^^^^^^^^^^^^^^^^^
psycopg2.errors.NotNullViolation: null value in column "price" of relation "dashboard_position" violates not-null constraint
DETAIL:  Failing row contains (37, 4281.44, 4375, 3000, 3000, d005aba4651f4d97a0b4ce6cece9d5a0, t, reaching_min_profit_exit_price, 0, f, 43.7, 598.6, null, 2037.16, 37.16, 1.86, 98.98, 85.03, 0, 1757085038, 1757409387, 0, t, 0.07, auto_exit_style_only_after_min_profit, 8, 0.46713208022382086).


The above exception was the direct cause of the following exception:

Traceback (most recent call last):
  File "C:\Users\user\Desktop\trade\dashboard\views_pages\pulse_handler.py", line 45, in handle_a_pulse
    position.save()
  File "C:\Users\user\Desktop\trade\dashboard\models\models_position.py", line 114, in save
    super(Position, self).save(*args, **kwargs)
  File "C:\Users\user\Desktop\p312\Lib\site-packages\django\db\models\base.py", line 902, in save
    self.save_base(
  File "C:\Users\user\Desktop\p312\Lib\site-packages\django\db\models\base.py", line 1008, in save_base
    updated = self._save_table(
              ^^^^^^^^^^^^^^^^^
  File "C:\Users\user\Desktop\p312\Lib\site-packages\django\db\models\base.py", line 1138, in _save_table
    updated = self._do_update(
              ^^^^^^^^^^^^^^^^
  File "C:\Users\user\Desktop\p312\Lib\site-packages\django\db\models\base.py", line 1203, in _do_update
    return filtered._update(values) > 0
           ^^^^^^^^^^^^^^^^^^^^^^^^
  File "C:\Users\user\Desktop\p312\Lib\site-packages\django\db\models\query.py", line 1286, in _update
    return query.get_compiler(self.db).execute_sql(ROW_COUNT)
           ^^^^^^^^^^^^^^^^^^^^^^^^^^^^^^^^^^^^^^^^^^^^^^^^^^
  File "C:\Users\user\Desktop\p312\Lib\site-packages\django\db\models\sql\compiler.py", line 2060, in execute_sql
    row_count = super().execute_sql(result_type)
                ^^^^^^^^^^^^^^^^^^^^^^^^^^^^^^^^
  File "C:\Users\user\Desktop\p312\Lib\site-packages\django\db\models\sql\compiler.py", line 1623, in execute_sql
    cursor.execute(sql, params)
  File "C:\Users\user\Desktop\p312\Lib\site-packages\django\db\backends\utils.py", line 122, in execute
    return super().execute(sql, params)
           ^^^^^^^^^^^^^^^^^^^^^^^^^^^^
  File "C:\Users\user\Desktop\p312\Lib\site-packages\django\db\backends\utils.py", line 79, in execute
    return self._execute_with_wrappers(
           ^^^^^^^^^^^^^^^^^^^^^^^^^^^^
  File "C:\Users\user\Desktop\p312\Lib\site-packages\django\db\backends\utils.py", line 92, in _execute_with_wrappers
    return executor(sql, params, many, context)
           ^^^^^^^^^^^^^^^^^^^^^^^^^^^^^^^^^^^^
  File "C:\Users\user\Desktop\p312\Lib\site-packages\django\db\backends\utils.py", line 100, in _execute
    with self.db.wrap_database_errors:
         ^^^^^^^^^^^^^^^^^^^^^^^^^^^^
  File "C:\Users\user\Desktop\p312\Lib\site-packages\django\db\utils.py", line 91, in __exit__
    raise dj_exc_value.with_traceback(traceback) from exc_value
  File "C:\Users\user\Desktop\p312\Lib\site-packages\django\db\backends\utils.py", line 105, in _execute
    return self.cursor.execute(sql, params)
           ^^^^^^^^^^^^^^^^^^^^^^^^^^^^^^^^
django.db.utils.IntegrityError: null value in column "price" of relation "dashboard_position" violates not-null constraint
DETAIL:  Failing row contains (37, 4281.44, 4375, 3000, 3000, d005aba4651f4d97a0b4ce6cece9d5a0, t, reaching_min_profit_exit_price, 0, f, 43.7, 598.6, null, 2037.16, 37.16, 1.86, 98.98, 85.03, 0, 1757085038, 1757409387, 0, t, 0.07, auto_exit_style_only_after_min_profit, 8, 0.46713208022382086).


2025-09-09 13:16:31.955766 - Traceback (most recent call last):
  File "C:\Users\user\Desktop\trade\dashboard\models\models_position.py", line 178, in evaluate
    if self.min_profit_exit_price < self.price:
       ^^^^^^^^^^^^^^^^^^^^^^^^^^^^^^^^^^^^^^^
TypeError: '<' not supported between instances of 'float' and 'NoneType'

During handling of the above exception, another exception occurred:

Traceback (most recent call last):
  File "C:\Users\user\Desktop\p312\Lib\site-packages\urllib3\connection.py", line 198, in _new_conn
    sock = connection.create_connection(
           ^^^^^^^^^^^^^^^^^^^^^^^^^^^^^
  File "C:\Users\user\Desktop\p312\Lib\site-packages\urllib3\util\connection.py", line 60, in create_connection
    for res in socket.getaddrinfo(host, port, family, socket.SOCK_STREAM):
               ^^^^^^^^^^^^^^^^^^^^^^^^^^^^^^^^^^^^^^^^^^^^^^^^^^^^^^^^^^
  File "C:\Users\user\AppData\Local\Programs\Python\Python312\Lib\socket.py", line 978, in getaddrinfo
    for res in _socket.getaddrinfo(host, port, family, type, proto, flags):
               ^^^^^^^^^^^^^^^^^^^^^^^^^^^^^^^^^^^^^^^^^^^^^^^^^^^^^^^^^^^
socket.gaierror: [Errno 11001] getaddrinfo failed

The above exception was the direct cause of the following exception:

Traceback (most recent call last):
  File "C:\Users\user\Desktop\p312\Lib\site-packages\urllib3\connectionpool.py", line 787, in urlopen
    response = self._make_request(
               ^^^^^^^^^^^^^^^^^^^
  File "C:\Users\user\Desktop\p312\Lib\site-packages\urllib3\connectionpool.py", line 488, in _make_request
    raise new_e
  File "C:\Users\user\Desktop\p312\Lib\site-packages\urllib3\connectionpool.py", line 464, in _make_request
    self._validate_conn(conn)
  File "C:\Users\user\Desktop\p312\Lib\site-packages\urllib3\connectionpool.py", line 1093, in _validate_conn
    conn.connect()
  File "C:\Users\user\Desktop\p312\Lib\site-packages\urllib3\connection.py", line 753, in connect
    self.sock = sock = self._new_conn()
                       ^^^^^^^^^^^^^^^^
  File "C:\Users\user\Desktop\p312\Lib\site-packages\urllib3\connection.py", line 205, in _new_conn
    raise NameResolutionError(self.host, self, e) from e
urllib3.exceptions.NameResolutionError: <urllib3.connection.HTTPSConnection object at 0x0000017CBB547B30>: Failed to resolve 'api.telegram.org' ([Errno 11001] getaddrinfo failed)

The above exception was the direct cause of the following exception:

Traceback (most recent call last):
  File "C:\Users\user\Desktop\p312\Lib\site-packages\requests\adapters.py", line 667, in send
    resp = conn.urlopen(
           ^^^^^^^^^^^^^
  File "C:\Users\user\Desktop\p312\Lib\site-packages\urllib3\connectionpool.py", line 841, in urlopen
    retries = retries.increment(
              ^^^^^^^^^^^^^^^^^^
  File "C:\Users\user\Desktop\p312\Lib\site-packages\urllib3\util\retry.py", line 519, in increment
    raise MaxRetryError(_pool, url, reason) from reason  # type: ignore[arg-type]
    ^^^^^^^^^^^^^^^^^^^^^^^^^^^^^^^^^^^^^^^^^^^^^^^^^^^
urllib3.exceptions.MaxRetryError: HTTPSConnectionPool(host='api.telegram.org', port=443): Max retries exceeded with url: /bot8452876784:AAHzQeMZQGmEA8PcqXnGwdyh5y7dBYjiCwg/sendMessage?chat_id=5214991865&text=%3Cb%3Eruntime%20error%3C/b%3E%0A%0ATraceback%20(most%20recent%20call%20last):%0A%20%20File%20%22C:%5CUsers%5Cuser%5CDesktop%5Ctrade%5Cdashboard%5Cmodels%5Cmodels_position.py%22,%20line%20178,%20in%20evaluate%0A%20%20%20%20if%20self.min_profit_exit_price%20%3C%20self.price:%0A%20%20%20%20%20%20%20%5E%5E%5E%5E%5E%5E%5E%5E%5E%5E%5E%5E%5E%5E%5E%5E%5E%5E%5E%5E%5E%5E%5E%5E%5E%5E%5E%5E%5E%5E%5E%5E%5E%5E%5E%5E%5E%5E%5E%0ATypeError:%20'%3C'%20not%20supported%20between%20instances%20of%20'float'%20and%20'NoneType'%0A&parse_mode=HTML (Caused by NameResolutionError("<urllib3.connection.HTTPSConnection object at 0x0000017CBB547B30>: Failed to resolve 'api.telegram.org' ([Errno 11001] getaddrinfo failed)"))

During handling of the above exception, another exception occurred:

Traceback (most recent call last):
  File "C:\Users\user\Desktop\trade\dashboard\modules\notification\notification.py", line 21, in send
    requests.get(url)
  File "C:\Users\user\Desktop\p312\Lib\site-packages\requests\api.py", line 73, in get
    return request("get", url, params=params, **kwargs)
           ^^^^^^^^^^^^^^^^^^^^^^^^^^^^^^^^^^^^^^^^^^^^
  File "C:\Users\user\Desktop\p312\Lib\site-packages\requests\api.py", line 59, in request
    return session.request(method=method, url=url, **kwargs)
           ^^^^^^^^^^^^^^^^^^^^^^^^^^^^^^^^^^^^^^^^^^^^^^^^^
  File "C:\Users\user\Desktop\p312\Lib\site-packages\requests\sessions.py", line 589, in request
    resp = self.send(prep, **send_kwargs)
           ^^^^^^^^^^^^^^^^^^^^^^^^^^^^^^
  File "C:\Users\user\Desktop\p312\Lib\site-packages\requests\sessions.py", line 703, in send
    r = adapter.send(request, **kwargs)
        ^^^^^^^^^^^^^^^^^^^^^^^^^^^^^^^
  File "C:\Users\user\Desktop\p312\Lib\site-packages\requests\adapters.py", line 700, in send
    raise ConnectionError(e, request=request)
requests.exceptions.ConnectionError: HTTPSConnectionPool(host='api.telegram.org', port=443): Max retries exceeded with url: /bot8452876784:AAHzQeMZQGmEA8PcqXnGwdyh5y7dBYjiCwg/sendMessage?chat_id=5214991865&text=%3Cb%3Eruntime%20error%3C/b%3E%0A%0ATraceback%20(most%20recent%20call%20last):%0A%20%20File%20%22C:%5CUsers%5Cuser%5CDesktop%5Ctrade%5Cdashboard%5Cmodels%5Cmodels_position.py%22,%20line%20178,%20in%20evaluate%0A%20%20%20%20if%20self.min_profit_exit_price%20%3C%20self.price:%0A%20%20%20%20%20%20%20%5E%5E%5E%5E%5E%5E%5E%5E%5E%5E%5E%5E%5E%5E%5E%5E%5E%5E%5E%5E%5E%5E%5E%5E%5E%5E%5E%5E%5E%5E%5E%5E%5E%5E%5E%5E%5E%5E%5E%0ATypeError:%20'%3C'%20not%20supported%20between%20instances%20of%20'float'%20and%20'NoneType'%0A&parse_mode=HTML (Caused by NameResolutionError("<urllib3.connection.HTTPSConnection object at 0x0000017CBB547B30>: Failed to resolve 'api.telegram.org' ([Errno 11001] getaddrinfo failed)"))

2025-09-09 13:16:31.963831 - Traceback (most recent call last):
  File "C:\Users\user\Desktop\p312\Lib\site-packages\django\db\backends\utils.py", line 105, in _execute
    return self.cursor.execute(sql, params)
           ^^^^^^^^^^^^^^^^^^^^^^^^^^^^^^^^
psycopg2.errors.NotNullViolation: null value in column "price" of relation "dashboard_position" violates not-null constraint
DETAIL:  Failing row contains (37, 4281.44, 4375, 3000, 3000, d005aba4651f4d97a0b4ce6cece9d5a0, t, reaching_min_profit_exit_price, 0, f, 43.7, 598.6, null, 2037.16, 37.16, 1.86, 98.98, 85.03, 0, 1757085038, 1757409391, 0, t, 0.07, auto_exit_style_only_after_min_profit, 8, 0.46713208022382086).


The above exception was the direct cause of the following exception:

Traceback (most recent call last):
  File "C:\Users\user\Desktop\trade\dashboard\views_pages\pulse_handler.py", line 45, in handle_a_pulse
    position.save()
  File "C:\Users\user\Desktop\trade\dashboard\models\models_position.py", line 114, in save
    super(Position, self).save(*args, **kwargs)
  File "C:\Users\user\Desktop\p312\Lib\site-packages\django\db\models\base.py", line 902, in save
    self.save_base(
  File "C:\Users\user\Desktop\p312\Lib\site-packages\django\db\models\base.py", line 1008, in save_base
    updated = self._save_table(
              ^^^^^^^^^^^^^^^^^
  File "C:\Users\user\Desktop\p312\Lib\site-packages\django\db\models\base.py", line 1138, in _save_table
    updated = self._do_update(
              ^^^^^^^^^^^^^^^^
  File "C:\Users\user\Desktop\p312\Lib\site-packages\django\db\models\base.py", line 1203, in _do_update
    return filtered._update(values) > 0
           ^^^^^^^^^^^^^^^^^^^^^^^^
  File "C:\Users\user\Desktop\p312\Lib\site-packages\django\db\models\query.py", line 1286, in _update
    return query.get_compiler(self.db).execute_sql(ROW_COUNT)
           ^^^^^^^^^^^^^^^^^^^^^^^^^^^^^^^^^^^^^^^^^^^^^^^^^^
  File "C:\Users\user\Desktop\p312\Lib\site-packages\django\db\models\sql\compiler.py", line 2060, in execute_sql
    row_count = super().execute_sql(result_type)
                ^^^^^^^^^^^^^^^^^^^^^^^^^^^^^^^^
  File "C:\Users\user\Desktop\p312\Lib\site-packages\django\db\models\sql\compiler.py", line 1623, in execute_sql
    cursor.execute(sql, params)
  File "C:\Users\user\Desktop\p312\Lib\site-packages\django\db\backends\utils.py", line 122, in execute
    return super().execute(sql, params)
           ^^^^^^^^^^^^^^^^^^^^^^^^^^^^
  File "C:\Users\user\Desktop\p312\Lib\site-packages\django\db\backends\utils.py", line 79, in execute
    return self._execute_with_wrappers(
           ^^^^^^^^^^^^^^^^^^^^^^^^^^^^
  File "C:\Users\user\Desktop\p312\Lib\site-packages\django\db\backends\utils.py", line 92, in _execute_with_wrappers
    return executor(sql, params, many, context)
           ^^^^^^^^^^^^^^^^^^^^^^^^^^^^^^^^^^^^
  File "C:\Users\user\Desktop\p312\Lib\site-packages\django\db\backends\utils.py", line 100, in _execute
    with self.db.wrap_database_errors:
         ^^^^^^^^^^^^^^^^^^^^^^^^^^^^
  File "C:\Users\user\Desktop\p312\Lib\site-packages\django\db\utils.py", line 91, in __exit__
    raise dj_exc_value.with_traceback(traceback) from exc_value
  File "C:\Users\user\Desktop\p312\Lib\site-packages\django\db\backends\utils.py", line 105, in _execute
    return self.cursor.execute(sql, params)
           ^^^^^^^^^^^^^^^^^^^^^^^^^^^^^^^^
django.db.utils.IntegrityError: null value in column "price" of relation "dashboard_position" violates not-null constraint
DETAIL:  Failing row contains (37, 4281.44, 4375, 3000, 3000, d005aba4651f4d97a0b4ce6cece9d5a0, t, reaching_min_profit_exit_price, 0, f, 43.7, 598.6, null, 2037.16, 37.16, 1.86, 98.98, 85.03, 0, 1757085038, 1757409391, 0, t, 0.07, auto_exit_style_only_after_min_profit, 8, 0.46713208022382086).


2025-09-09 13:16:36.046970 - Traceback (most recent call last):
  File "C:\Users\user\Desktop\trade\dashboard\models\models_position.py", line 178, in evaluate
    if self.min_profit_exit_price < self.price:
       ^^^^^^^^^^^^^^^^^^^^^^^^^^^^^^^^^^^^^^^
TypeError: '<' not supported between instances of 'float' and 'NoneType'

During handling of the above exception, another exception occurred:

Traceback (most recent call last):
  File "C:\Users\user\Desktop\p312\Lib\site-packages\urllib3\connection.py", line 198, in _new_conn
    sock = connection.create_connection(
           ^^^^^^^^^^^^^^^^^^^^^^^^^^^^^
  File "C:\Users\user\Desktop\p312\Lib\site-packages\urllib3\util\connection.py", line 60, in create_connection
    for res in socket.getaddrinfo(host, port, family, socket.SOCK_STREAM):
               ^^^^^^^^^^^^^^^^^^^^^^^^^^^^^^^^^^^^^^^^^^^^^^^^^^^^^^^^^^
  File "C:\Users\user\AppData\Local\Programs\Python\Python312\Lib\socket.py", line 978, in getaddrinfo
    for res in _socket.getaddrinfo(host, port, family, type, proto, flags):
               ^^^^^^^^^^^^^^^^^^^^^^^^^^^^^^^^^^^^^^^^^^^^^^^^^^^^^^^^^^^
socket.gaierror: [Errno 11001] getaddrinfo failed

The above exception was the direct cause of the following exception:

Traceback (most recent call last):
  File "C:\Users\user\Desktop\p312\Lib\site-packages\urllib3\connectionpool.py", line 787, in urlopen
    response = self._make_request(
               ^^^^^^^^^^^^^^^^^^^
  File "C:\Users\user\Desktop\p312\Lib\site-packages\urllib3\connectionpool.py", line 488, in _make_request
    raise new_e
  File "C:\Users\user\Desktop\p312\Lib\site-packages\urllib3\connectionpool.py", line 464, in _make_request
    self._validate_conn(conn)
  File "C:\Users\user\Desktop\p312\Lib\site-packages\urllib3\connectionpool.py", line 1093, in _validate_conn
    conn.connect()
  File "C:\Users\user\Desktop\p312\Lib\site-packages\urllib3\connection.py", line 753, in connect
    self.sock = sock = self._new_conn()
                       ^^^^^^^^^^^^^^^^
  File "C:\Users\user\Desktop\p312\Lib\site-packages\urllib3\connection.py", line 205, in _new_conn
    raise NameResolutionError(self.host, self, e) from e
urllib3.exceptions.NameResolutionError: <urllib3.connection.HTTPSConnection object at 0x0000017CBB1C0FB0>: Failed to resolve 'api.telegram.org' ([Errno 11001] getaddrinfo failed)

The above exception was the direct cause of the following exception:

Traceback (most recent call last):
  File "C:\Users\user\Desktop\p312\Lib\site-packages\requests\adapters.py", line 667, in send
    resp = conn.urlopen(
           ^^^^^^^^^^^^^
  File "C:\Users\user\Desktop\p312\Lib\site-packages\urllib3\connectionpool.py", line 841, in urlopen
    retries = retries.increment(
              ^^^^^^^^^^^^^^^^^^
  File "C:\Users\user\Desktop\p312\Lib\site-packages\urllib3\util\retry.py", line 519, in increment
    raise MaxRetryError(_pool, url, reason) from reason  # type: ignore[arg-type]
    ^^^^^^^^^^^^^^^^^^^^^^^^^^^^^^^^^^^^^^^^^^^^^^^^^^^
urllib3.exceptions.MaxRetryError: HTTPSConnectionPool(host='api.telegram.org', port=443): Max retries exceeded with url: /bot8452876784:AAHzQeMZQGmEA8PcqXnGwdyh5y7dBYjiCwg/sendMessage?chat_id=5214991865&text=%3Cb%3Eruntime%20error%3C/b%3E%0A%0ATraceback%20(most%20recent%20call%20last):%0A%20%20File%20%22C:%5CUsers%5Cuser%5CDesktop%5Ctrade%5Cdashboard%5Cmodels%5Cmodels_position.py%22,%20line%20178,%20in%20evaluate%0A%20%20%20%20if%20self.min_profit_exit_price%20%3C%20self.price:%0A%20%20%20%20%20%20%20%5E%5E%5E%5E%5E%5E%5E%5E%5E%5E%5E%5E%5E%5E%5E%5E%5E%5E%5E%5E%5E%5E%5E%5E%5E%5E%5E%5E%5E%5E%5E%5E%5E%5E%5E%5E%5E%5E%5E%0ATypeError:%20'%3C'%20not%20supported%20between%20instances%20of%20'float'%20and%20'NoneType'%0A&parse_mode=HTML (Caused by NameResolutionError("<urllib3.connection.HTTPSConnection object at 0x0000017CBB1C0FB0>: Failed to resolve 'api.telegram.org' ([Errno 11001] getaddrinfo failed)"))

During handling of the above exception, another exception occurred:

Traceback (most recent call last):
  File "C:\Users\user\Desktop\trade\dashboard\modules\notification\notification.py", line 21, in send
    requests.get(url)
  File "C:\Users\user\Desktop\p312\Lib\site-packages\requests\api.py", line 73, in get
    return request("get", url, params=params, **kwargs)
           ^^^^^^^^^^^^^^^^^^^^^^^^^^^^^^^^^^^^^^^^^^^^
  File "C:\Users\user\Desktop\p312\Lib\site-packages\requests\api.py", line 59, in request
    return session.request(method=method, url=url, **kwargs)
           ^^^^^^^^^^^^^^^^^^^^^^^^^^^^^^^^^^^^^^^^^^^^^^^^^
  File "C:\Users\user\Desktop\p312\Lib\site-packages\requests\sessions.py", line 589, in request
    resp = self.send(prep, **send_kwargs)
           ^^^^^^^^^^^^^^^^^^^^^^^^^^^^^^
  File "C:\Users\user\Desktop\p312\Lib\site-packages\requests\sessions.py", line 703, in send
    r = adapter.send(request, **kwargs)
        ^^^^^^^^^^^^^^^^^^^^^^^^^^^^^^^
  File "C:\Users\user\Desktop\p312\Lib\site-packages\requests\adapters.py", line 700, in send
    raise ConnectionError(e, request=request)
requests.exceptions.ConnectionError: HTTPSConnectionPool(host='api.telegram.org', port=443): Max retries exceeded with url: /bot8452876784:AAHzQeMZQGmEA8PcqXnGwdyh5y7dBYjiCwg/sendMessage?chat_id=5214991865&text=%3Cb%3Eruntime%20error%3C/b%3E%0A%0ATraceback%20(most%20recent%20call%20last):%0A%20%20File%20%22C:%5CUsers%5Cuser%5CDesktop%5Ctrade%5Cdashboard%5Cmodels%5Cmodels_position.py%22,%20line%20178,%20in%20evaluate%0A%20%20%20%20if%20self.min_profit_exit_price%20%3C%20self.price:%0A%20%20%20%20%20%20%20%5E%5E%5E%5E%5E%5E%5E%5E%5E%5E%5E%5E%5E%5E%5E%5E%5E%5E%5E%5E%5E%5E%5E%5E%5E%5E%5E%5E%5E%5E%5E%5E%5E%5E%5E%5E%5E%5E%5E%0ATypeError:%20'%3C'%20not%20supported%20between%20instances%20of%20'float'%20and%20'NoneType'%0A&parse_mode=HTML (Caused by NameResolutionError("<urllib3.connection.HTTPSConnection object at 0x0000017CBB1C0FB0>: Failed to resolve 'api.telegram.org' ([Errno 11001] getaddrinfo failed)"))

2025-09-09 13:16:36.054967 - Traceback (most recent call last):
  File "C:\Users\user\Desktop\p312\Lib\site-packages\django\db\backends\utils.py", line 105, in _execute
    return self.cursor.execute(sql, params)
           ^^^^^^^^^^^^^^^^^^^^^^^^^^^^^^^^
psycopg2.errors.NotNullViolation: null value in column "price" of relation "dashboard_position" violates not-null constraint
DETAIL:  Failing row contains (37, 4281.44, 4375, 3000, 3000, d005aba4651f4d97a0b4ce6cece9d5a0, t, reaching_min_profit_exit_price, 0, f, 43.7, 598.6, null, 2037.16, 37.16, 1.86, 98.98, 85.03, 0, 1757085038, 1757409396, 0, t, 0.07, auto_exit_style_only_after_min_profit, 8, 0.46713208022382086).


The above exception was the direct cause of the following exception:

Traceback (most recent call last):
  File "C:\Users\user\Desktop\trade\dashboard\views_pages\pulse_handler.py", line 45, in handle_a_pulse
    position.save()
  File "C:\Users\user\Desktop\trade\dashboard\models\models_position.py", line 114, in save
    super(Position, self).save(*args, **kwargs)
  File "C:\Users\user\Desktop\p312\Lib\site-packages\django\db\models\base.py", line 902, in save
    self.save_base(
  File "C:\Users\user\Desktop\p312\Lib\site-packages\django\db\models\base.py", line 1008, in save_base
    updated = self._save_table(
              ^^^^^^^^^^^^^^^^^
  File "C:\Users\user\Desktop\p312\Lib\site-packages\django\db\models\base.py", line 1138, in _save_table
    updated = self._do_update(
              ^^^^^^^^^^^^^^^^
  File "C:\Users\user\Desktop\p312\Lib\site-packages\django\db\models\base.py", line 1203, in _do_update
    return filtered._update(values) > 0
           ^^^^^^^^^^^^^^^^^^^^^^^^
  File "C:\Users\user\Desktop\p312\Lib\site-packages\django\db\models\query.py", line 1286, in _update
    return query.get_compiler(self.db).execute_sql(ROW_COUNT)
           ^^^^^^^^^^^^^^^^^^^^^^^^^^^^^^^^^^^^^^^^^^^^^^^^^^
  File "C:\Users\user\Desktop\p312\Lib\site-packages\django\db\models\sql\compiler.py", line 2060, in execute_sql
    row_count = super().execute_sql(result_type)
                ^^^^^^^^^^^^^^^^^^^^^^^^^^^^^^^^
  File "C:\Users\user\Desktop\p312\Lib\site-packages\django\db\models\sql\compiler.py", line 1623, in execute_sql
    cursor.execute(sql, params)
  File "C:\Users\user\Desktop\p312\Lib\site-packages\django\db\backends\utils.py", line 122, in execute
    return super().execute(sql, params)
           ^^^^^^^^^^^^^^^^^^^^^^^^^^^^
  File "C:\Users\user\Desktop\p312\Lib\site-packages\django\db\backends\utils.py", line 79, in execute
    return self._execute_with_wrappers(
           ^^^^^^^^^^^^^^^^^^^^^^^^^^^^
  File "C:\Users\user\Desktop\p312\Lib\site-packages\django\db\backends\utils.py", line 92, in _execute_with_wrappers
    return executor(sql, params, many, context)
           ^^^^^^^^^^^^^^^^^^^^^^^^^^^^^^^^^^^^
  File "C:\Users\user\Desktop\p312\Lib\site-packages\django\db\backends\utils.py", line 100, in _execute
    with self.db.wrap_database_errors:
         ^^^^^^^^^^^^^^^^^^^^^^^^^^^^
  File "C:\Users\user\Desktop\p312\Lib\site-packages\django\db\utils.py", line 91, in __exit__
    raise dj_exc_value.with_traceback(traceback) from exc_value
  File "C:\Users\user\Desktop\p312\Lib\site-packages\django\db\backends\utils.py", line 105, in _execute
    return self.cursor.execute(sql, params)
           ^^^^^^^^^^^^^^^^^^^^^^^^^^^^^^^^
django.db.utils.IntegrityError: null value in column "price" of relation "dashboard_position" violates not-null constraint
DETAIL:  Failing row contains (37, 4281.44, 4375, 3000, 3000, d005aba4651f4d97a0b4ce6cece9d5a0, t, reaching_min_profit_exit_price, 0, f, 43.7, 598.6, null, 2037.16, 37.16, 1.86, 98.98, 85.03, 0, 1757085038, 1757409396, 0, t, 0.07, auto_exit_style_only_after_min_profit, 8, 0.46713208022382086).


2025-09-09 13:16:40.176056 - Traceback (most recent call last):
  File "C:\Users\user\Desktop\trade\dashboard\models\models_position.py", line 178, in evaluate
    if self.min_profit_exit_price < self.price:
       ^^^^^^^^^^^^^^^^^^^^^^^^^^^^^^^^^^^^^^^
TypeError: '<' not supported between instances of 'float' and 'NoneType'

During handling of the above exception, another exception occurred:

Traceback (most recent call last):
  File "C:\Users\user\Desktop\p312\Lib\site-packages\urllib3\connection.py", line 198, in _new_conn
    sock = connection.create_connection(
           ^^^^^^^^^^^^^^^^^^^^^^^^^^^^^
  File "C:\Users\user\Desktop\p312\Lib\site-packages\urllib3\util\connection.py", line 60, in create_connection
    for res in socket.getaddrinfo(host, port, family, socket.SOCK_STREAM):
               ^^^^^^^^^^^^^^^^^^^^^^^^^^^^^^^^^^^^^^^^^^^^^^^^^^^^^^^^^^
  File "C:\Users\user\AppData\Local\Programs\Python\Python312\Lib\socket.py", line 978, in getaddrinfo
    for res in _socket.getaddrinfo(host, port, family, type, proto, flags):
               ^^^^^^^^^^^^^^^^^^^^^^^^^^^^^^^^^^^^^^^^^^^^^^^^^^^^^^^^^^^
socket.gaierror: [Errno 11001] getaddrinfo failed

The above exception was the direct cause of the following exception:

Traceback (most recent call last):
  File "C:\Users\user\Desktop\p312\Lib\site-packages\urllib3\connectionpool.py", line 787, in urlopen
    response = self._make_request(
               ^^^^^^^^^^^^^^^^^^^
  File "C:\Users\user\Desktop\p312\Lib\site-packages\urllib3\connectionpool.py", line 488, in _make_request
    raise new_e
  File "C:\Users\user\Desktop\p312\Lib\site-packages\urllib3\connectionpool.py", line 464, in _make_request
    self._validate_conn(conn)
  File "C:\Users\user\Desktop\p312\Lib\site-packages\urllib3\connectionpool.py", line 1093, in _validate_conn
    conn.connect()
  File "C:\Users\user\Desktop\p312\Lib\site-packages\urllib3\connection.py", line 753, in connect
    self.sock = sock = self._new_conn()
                       ^^^^^^^^^^^^^^^^
  File "C:\Users\user\Desktop\p312\Lib\site-packages\urllib3\connection.py", line 205, in _new_conn
    raise NameResolutionError(self.host, self, e) from e
urllib3.exceptions.NameResolutionError: <urllib3.connection.HTTPSConnection object at 0x0000017CBB486300>: Failed to resolve 'api.telegram.org' ([Errno 11001] getaddrinfo failed)

The above exception was the direct cause of the following exception:

Traceback (most recent call last):
  File "C:\Users\user\Desktop\p312\Lib\site-packages\requests\adapters.py", line 667, in send
    resp = conn.urlopen(
           ^^^^^^^^^^^^^
  File "C:\Users\user\Desktop\p312\Lib\site-packages\urllib3\connectionpool.py", line 841, in urlopen
    retries = retries.increment(
              ^^^^^^^^^^^^^^^^^^
  File "C:\Users\user\Desktop\p312\Lib\site-packages\urllib3\util\retry.py", line 519, in increment
    raise MaxRetryError(_pool, url, reason) from reason  # type: ignore[arg-type]
    ^^^^^^^^^^^^^^^^^^^^^^^^^^^^^^^^^^^^^^^^^^^^^^^^^^^
urllib3.exceptions.MaxRetryError: HTTPSConnectionPool(host='api.telegram.org', port=443): Max retries exceeded with url: /bot8452876784:AAHzQeMZQGmEA8PcqXnGwdyh5y7dBYjiCwg/sendMessage?chat_id=5214991865&text=%3Cb%3Eruntime%20error%3C/b%3E%0A%0ATraceback%20(most%20recent%20call%20last):%0A%20%20File%20%22C:%5CUsers%5Cuser%5CDesktop%5Ctrade%5Cdashboard%5Cmodels%5Cmodels_position.py%22,%20line%20178,%20in%20evaluate%0A%20%20%20%20if%20self.min_profit_exit_price%20%3C%20self.price:%0A%20%20%20%20%20%20%20%5E%5E%5E%5E%5E%5E%5E%5E%5E%5E%5E%5E%5E%5E%5E%5E%5E%5E%5E%5E%5E%5E%5E%5E%5E%5E%5E%5E%5E%5E%5E%5E%5E%5E%5E%5E%5E%5E%5E%0ATypeError:%20'%3C'%20not%20supported%20between%20instances%20of%20'float'%20and%20'NoneType'%0A&parse_mode=HTML (Caused by NameResolutionError("<urllib3.connection.HTTPSConnection object at 0x0000017CBB486300>: Failed to resolve 'api.telegram.org' ([Errno 11001] getaddrinfo failed)"))

During handling of the above exception, another exception occurred:

Traceback (most recent call last):
  File "C:\Users\user\Desktop\trade\dashboard\modules\notification\notification.py", line 21, in send
    requests.get(url)
  File "C:\Users\user\Desktop\p312\Lib\site-packages\requests\api.py", line 73, in get
    return request("get", url, params=params, **kwargs)
           ^^^^^^^^^^^^^^^^^^^^^^^^^^^^^^^^^^^^^^^^^^^^
  File "C:\Users\user\Desktop\p312\Lib\site-packages\requests\api.py", line 59, in request
    return session.request(method=method, url=url, **kwargs)
           ^^^^^^^^^^^^^^^^^^^^^^^^^^^^^^^^^^^^^^^^^^^^^^^^^
  File "C:\Users\user\Desktop\p312\Lib\site-packages\requests\sessions.py", line 589, in request
    resp = self.send(prep, **send_kwargs)
           ^^^^^^^^^^^^^^^^^^^^^^^^^^^^^^
  File "C:\Users\user\Desktop\p312\Lib\site-packages\requests\sessions.py", line 703, in send
    r = adapter.send(request, **kwargs)
        ^^^^^^^^^^^^^^^^^^^^^^^^^^^^^^^
  File "C:\Users\user\Desktop\p312\Lib\site-packages\requests\adapters.py", line 700, in send
    raise ConnectionError(e, request=request)
requests.exceptions.ConnectionError: HTTPSConnectionPool(host='api.telegram.org', port=443): Max retries exceeded with url: /bot8452876784:AAHzQeMZQGmEA8PcqXnGwdyh5y7dBYjiCwg/sendMessage?chat_id=5214991865&text=%3Cb%3Eruntime%20error%3C/b%3E%0A%0ATraceback%20(most%20recent%20call%20last):%0A%20%20File%20%22C:%5CUsers%5Cuser%5CDesktop%5Ctrade%5Cdashboard%5Cmodels%5Cmodels_position.py%22,%20line%20178,%20in%20evaluate%0A%20%20%20%20if%20self.min_profit_exit_price%20%3C%20self.price:%0A%20%20%20%20%20%20%20%5E%5E%5E%5E%5E%5E%5E%5E%5E%5E%5E%5E%5E%5E%5E%5E%5E%5E%5E%5E%5E%5E%5E%5E%5E%5E%5E%5E%5E%5E%5E%5E%5E%5E%5E%5E%5E%5E%5E%0ATypeError:%20'%3C'%20not%20supported%20between%20instances%20of%20'float'%20and%20'NoneType'%0A&parse_mode=HTML (Caused by NameResolutionError("<urllib3.connection.HTTPSConnection object at 0x0000017CBB486300>: Failed to resolve 'api.telegram.org' ([Errno 11001] getaddrinfo failed)"))

2025-09-09 13:16:40.184059 - Traceback (most recent call last):
  File "C:\Users\user\Desktop\p312\Lib\site-packages\django\db\backends\utils.py", line 105, in _execute
    return self.cursor.execute(sql, params)
           ^^^^^^^^^^^^^^^^^^^^^^^^^^^^^^^^
psycopg2.errors.NotNullViolation: null value in column "price" of relation "dashboard_position" violates not-null constraint
DETAIL:  Failing row contains (37, 4281.44, 4375, 3000, 3000, d005aba4651f4d97a0b4ce6cece9d5a0, t, reaching_min_profit_exit_price, 0, f, 43.7, 598.6, null, 2037.16, 37.16, 1.86, 98.98, 85.03, 0, 1757085038, 1757409400, 0, t, 0.07, auto_exit_style_only_after_min_profit, 8, 0.46713208022382086).


The above exception was the direct cause of the following exception:

Traceback (most recent call last):
  File "C:\Users\user\Desktop\trade\dashboard\views_pages\pulse_handler.py", line 45, in handle_a_pulse
    position.save()
  File "C:\Users\user\Desktop\trade\dashboard\models\models_position.py", line 114, in save
    super(Position, self).save(*args, **kwargs)
  File "C:\Users\user\Desktop\p312\Lib\site-packages\django\db\models\base.py", line 902, in save
    self.save_base(
  File "C:\Users\user\Desktop\p312\Lib\site-packages\django\db\models\base.py", line 1008, in save_base
    updated = self._save_table(
              ^^^^^^^^^^^^^^^^^
  File "C:\Users\user\Desktop\p312\Lib\site-packages\django\db\models\base.py", line 1138, in _save_table
    updated = self._do_update(
              ^^^^^^^^^^^^^^^^
  File "C:\Users\user\Desktop\p312\Lib\site-packages\django\db\models\base.py", line 1203, in _do_update
    return filtered._update(values) > 0
           ^^^^^^^^^^^^^^^^^^^^^^^^
  File "C:\Users\user\Desktop\p312\Lib\site-packages\django\db\models\query.py", line 1286, in _update
    return query.get_compiler(self.db).execute_sql(ROW_COUNT)
           ^^^^^^^^^^^^^^^^^^^^^^^^^^^^^^^^^^^^^^^^^^^^^^^^^^
  File "C:\Users\user\Desktop\p312\Lib\site-packages\django\db\models\sql\compiler.py", line 2060, in execute_sql
    row_count = super().execute_sql(result_type)
                ^^^^^^^^^^^^^^^^^^^^^^^^^^^^^^^^
  File "C:\Users\user\Desktop\p312\Lib\site-packages\django\db\models\sql\compiler.py", line 1623, in execute_sql
    cursor.execute(sql, params)
  File "C:\Users\user\Desktop\p312\Lib\site-packages\django\db\backends\utils.py", line 122, in execute
    return super().execute(sql, params)
           ^^^^^^^^^^^^^^^^^^^^^^^^^^^^
  File "C:\Users\user\Desktop\p312\Lib\site-packages\django\db\backends\utils.py", line 79, in execute
    return self._execute_with_wrappers(
           ^^^^^^^^^^^^^^^^^^^^^^^^^^^^
  File "C:\Users\user\Desktop\p312\Lib\site-packages\django\db\backends\utils.py", line 92, in _execute_with_wrappers
    return executor(sql, params, many, context)
           ^^^^^^^^^^^^^^^^^^^^^^^^^^^^^^^^^^^^
  File "C:\Users\user\Desktop\p312\Lib\site-packages\django\db\backends\utils.py", line 100, in _execute
    with self.db.wrap_database_errors:
         ^^^^^^^^^^^^^^^^^^^^^^^^^^^^
  File "C:\Users\user\Desktop\p312\Lib\site-packages\django\db\utils.py", line 91, in __exit__
    raise dj_exc_value.with_traceback(traceback) from exc_value
  File "C:\Users\user\Desktop\p312\Lib\site-packages\django\db\backends\utils.py", line 105, in _execute
    return self.cursor.execute(sql, params)
           ^^^^^^^^^^^^^^^^^^^^^^^^^^^^^^^^
django.db.utils.IntegrityError: null value in column "price" of relation "dashboard_position" violates not-null constraint
DETAIL:  Failing row contains (37, 4281.44, 4375, 3000, 3000, d005aba4651f4d97a0b4ce6cece9d5a0, t, reaching_min_profit_exit_price, 0, f, 43.7, 598.6, null, 2037.16, 37.16, 1.86, 98.98, 85.03, 0, 1757085038, 1757409400, 0, t, 0.07, auto_exit_style_only_after_min_profit, 8, 0.46713208022382086).


2025-09-09 13:16:44.273025 - Traceback (most recent call last):
  File "C:\Users\user\Desktop\trade\dashboard\models\models_position.py", line 178, in evaluate
    if self.min_profit_exit_price < self.price:
       ^^^^^^^^^^^^^^^^^^^^^^^^^^^^^^^^^^^^^^^
TypeError: '<' not supported between instances of 'float' and 'NoneType'

During handling of the above exception, another exception occurred:

Traceback (most recent call last):
  File "C:\Users\user\Desktop\p312\Lib\site-packages\urllib3\connection.py", line 198, in _new_conn
    sock = connection.create_connection(
           ^^^^^^^^^^^^^^^^^^^^^^^^^^^^^
  File "C:\Users\user\Desktop\p312\Lib\site-packages\urllib3\util\connection.py", line 60, in create_connection
    for res in socket.getaddrinfo(host, port, family, socket.SOCK_STREAM):
               ^^^^^^^^^^^^^^^^^^^^^^^^^^^^^^^^^^^^^^^^^^^^^^^^^^^^^^^^^^
  File "C:\Users\user\AppData\Local\Programs\Python\Python312\Lib\socket.py", line 978, in getaddrinfo
    for res in _socket.getaddrinfo(host, port, family, type, proto, flags):
               ^^^^^^^^^^^^^^^^^^^^^^^^^^^^^^^^^^^^^^^^^^^^^^^^^^^^^^^^^^^
socket.gaierror: [Errno 11001] getaddrinfo failed

The above exception was the direct cause of the following exception:

Traceback (most recent call last):
  File "C:\Users\user\Desktop\p312\Lib\site-packages\urllib3\connectionpool.py", line 787, in urlopen
    response = self._make_request(
               ^^^^^^^^^^^^^^^^^^^
  File "C:\Users\user\Desktop\p312\Lib\site-packages\urllib3\connectionpool.py", line 488, in _make_request
    raise new_e
  File "C:\Users\user\Desktop\p312\Lib\site-packages\urllib3\connectionpool.py", line 464, in _make_request
    self._validate_conn(conn)
  File "C:\Users\user\Desktop\p312\Lib\site-packages\urllib3\connectionpool.py", line 1093, in _validate_conn
    conn.connect()
  File "C:\Users\user\Desktop\p312\Lib\site-packages\urllib3\connection.py", line 753, in connect
    self.sock = sock = self._new_conn()
                       ^^^^^^^^^^^^^^^^
  File "C:\Users\user\Desktop\p312\Lib\site-packages\urllib3\connection.py", line 205, in _new_conn
    raise NameResolutionError(self.host, self, e) from e
urllib3.exceptions.NameResolutionError: <urllib3.connection.HTTPSConnection object at 0x0000017CBB29C410>: Failed to resolve 'api.telegram.org' ([Errno 11001] getaddrinfo failed)

The above exception was the direct cause of the following exception:

Traceback (most recent call last):
  File "C:\Users\user\Desktop\p312\Lib\site-packages\requests\adapters.py", line 667, in send
    resp = conn.urlopen(
           ^^^^^^^^^^^^^
  File "C:\Users\user\Desktop\p312\Lib\site-packages\urllib3\connectionpool.py", line 841, in urlopen
    retries = retries.increment(
              ^^^^^^^^^^^^^^^^^^
  File "C:\Users\user\Desktop\p312\Lib\site-packages\urllib3\util\retry.py", line 519, in increment
    raise MaxRetryError(_pool, url, reason) from reason  # type: ignore[arg-type]
    ^^^^^^^^^^^^^^^^^^^^^^^^^^^^^^^^^^^^^^^^^^^^^^^^^^^
urllib3.exceptions.MaxRetryError: HTTPSConnectionPool(host='api.telegram.org', port=443): Max retries exceeded with url: /bot8452876784:AAHzQeMZQGmEA8PcqXnGwdyh5y7dBYjiCwg/sendMessage?chat_id=5214991865&text=%3Cb%3Eruntime%20error%3C/b%3E%0A%0ATraceback%20(most%20recent%20call%20last):%0A%20%20File%20%22C:%5CUsers%5Cuser%5CDesktop%5Ctrade%5Cdashboard%5Cmodels%5Cmodels_position.py%22,%20line%20178,%20in%20evaluate%0A%20%20%20%20if%20self.min_profit_exit_price%20%3C%20self.price:%0A%20%20%20%20%20%20%20%5E%5E%5E%5E%5E%5E%5E%5E%5E%5E%5E%5E%5E%5E%5E%5E%5E%5E%5E%5E%5E%5E%5E%5E%5E%5E%5E%5E%5E%5E%5E%5E%5E%5E%5E%5E%5E%5E%5E%0ATypeError:%20'%3C'%20not%20supported%20between%20instances%20of%20'float'%20and%20'NoneType'%0A&parse_mode=HTML (Caused by NameResolutionError("<urllib3.connection.HTTPSConnection object at 0x0000017CBB29C410>: Failed to resolve 'api.telegram.org' ([Errno 11001] getaddrinfo failed)"))

During handling of the above exception, another exception occurred:

Traceback (most recent call last):
  File "C:\Users\user\Desktop\trade\dashboard\modules\notification\notification.py", line 21, in send
    requests.get(url)
  File "C:\Users\user\Desktop\p312\Lib\site-packages\requests\api.py", line 73, in get
    return request("get", url, params=params, **kwargs)
           ^^^^^^^^^^^^^^^^^^^^^^^^^^^^^^^^^^^^^^^^^^^^
  File "C:\Users\user\Desktop\p312\Lib\site-packages\requests\api.py", line 59, in request
    return session.request(method=method, url=url, **kwargs)
           ^^^^^^^^^^^^^^^^^^^^^^^^^^^^^^^^^^^^^^^^^^^^^^^^^
  File "C:\Users\user\Desktop\p312\Lib\site-packages\requests\sessions.py", line 589, in request
    resp = self.send(prep, **send_kwargs)
           ^^^^^^^^^^^^^^^^^^^^^^^^^^^^^^
  File "C:\Users\user\Desktop\p312\Lib\site-packages\requests\sessions.py", line 703, in send
    r = adapter.send(request, **kwargs)
        ^^^^^^^^^^^^^^^^^^^^^^^^^^^^^^^
  File "C:\Users\user\Desktop\p312\Lib\site-packages\requests\adapters.py", line 700, in send
    raise ConnectionError(e, request=request)
requests.exceptions.ConnectionError: HTTPSConnectionPool(host='api.telegram.org', port=443): Max retries exceeded with url: /bot8452876784:AAHzQeMZQGmEA8PcqXnGwdyh5y7dBYjiCwg/sendMessage?chat_id=5214991865&text=%3Cb%3Eruntime%20error%3C/b%3E%0A%0ATraceback%20(most%20recent%20call%20last):%0A%20%20File%20%22C:%5CUsers%5Cuser%5CDesktop%5Ctrade%5Cdashboard%5Cmodels%5Cmodels_position.py%22,%20line%20178,%20in%20evaluate%0A%20%20%20%20if%20self.min_profit_exit_price%20%3C%20self.price:%0A%20%20%20%20%20%20%20%5E%5E%5E%5E%5E%5E%5E%5E%5E%5E%5E%5E%5E%5E%5E%5E%5E%5E%5E%5E%5E%5E%5E%5E%5E%5E%5E%5E%5E%5E%5E%5E%5E%5E%5E%5E%5E%5E%5E%0ATypeError:%20'%3C'%20not%20supported%20between%20instances%20of%20'float'%20and%20'NoneType'%0A&parse_mode=HTML (Caused by NameResolutionError("<urllib3.connection.HTTPSConnection object at 0x0000017CBB29C410>: Failed to resolve 'api.telegram.org' ([Errno 11001] getaddrinfo failed)"))

2025-09-09 13:16:44.286023 - Traceback (most recent call last):
  File "C:\Users\user\Desktop\p312\Lib\site-packages\django\db\backends\utils.py", line 105, in _execute
    return self.cursor.execute(sql, params)
           ^^^^^^^^^^^^^^^^^^^^^^^^^^^^^^^^
psycopg2.errors.NotNullViolation: null value in column "price" of relation "dashboard_position" violates not-null constraint
DETAIL:  Failing row contains (37, 4281.44, 4375, 3000, 3000, d005aba4651f4d97a0b4ce6cece9d5a0, t, reaching_min_profit_exit_price, 0, f, 43.7, 598.6, null, 2037.16, 37.16, 1.86, 98.98, 85.03, 0, 1757085038, 1757409404, 0, t, 0.07, auto_exit_style_only_after_min_profit, 8, 0.46713208022382086).


The above exception was the direct cause of the following exception:

Traceback (most recent call last):
  File "C:\Users\user\Desktop\trade\dashboard\views_pages\pulse_handler.py", line 45, in handle_a_pulse
    position.save()
  File "C:\Users\user\Desktop\trade\dashboard\models\models_position.py", line 114, in save
    super(Position, self).save(*args, **kwargs)
  File "C:\Users\user\Desktop\p312\Lib\site-packages\django\db\models\base.py", line 902, in save
    self.save_base(
  File "C:\Users\user\Desktop\p312\Lib\site-packages\django\db\models\base.py", line 1008, in save_base
    updated = self._save_table(
              ^^^^^^^^^^^^^^^^^
  File "C:\Users\user\Desktop\p312\Lib\site-packages\django\db\models\base.py", line 1138, in _save_table
    updated = self._do_update(
              ^^^^^^^^^^^^^^^^
  File "C:\Users\user\Desktop\p312\Lib\site-packages\django\db\models\base.py", line 1203, in _do_update
    return filtered._update(values) > 0
           ^^^^^^^^^^^^^^^^^^^^^^^^
  File "C:\Users\user\Desktop\p312\Lib\site-packages\django\db\models\query.py", line 1286, in _update
    return query.get_compiler(self.db).execute_sql(ROW_COUNT)
           ^^^^^^^^^^^^^^^^^^^^^^^^^^^^^^^^^^^^^^^^^^^^^^^^^^
  File "C:\Users\user\Desktop\p312\Lib\site-packages\django\db\models\sql\compiler.py", line 2060, in execute_sql
    row_count = super().execute_sql(result_type)
                ^^^^^^^^^^^^^^^^^^^^^^^^^^^^^^^^
  File "C:\Users\user\Desktop\p312\Lib\site-packages\django\db\models\sql\compiler.py", line 1623, in execute_sql
    cursor.execute(sql, params)
  File "C:\Users\user\Desktop\p312\Lib\site-packages\django\db\backends\utils.py", line 122, in execute
    return super().execute(sql, params)
           ^^^^^^^^^^^^^^^^^^^^^^^^^^^^
  File "C:\Users\user\Desktop\p312\Lib\site-packages\django\db\backends\utils.py", line 79, in execute
    return self._execute_with_wrappers(
           ^^^^^^^^^^^^^^^^^^^^^^^^^^^^
  File "C:\Users\user\Desktop\p312\Lib\site-packages\django\db\backends\utils.py", line 92, in _execute_with_wrappers
    return executor(sql, params, many, context)
           ^^^^^^^^^^^^^^^^^^^^^^^^^^^^^^^^^^^^
  File "C:\Users\user\Desktop\p312\Lib\site-packages\django\db\backends\utils.py", line 100, in _execute
    with self.db.wrap_database_errors:
         ^^^^^^^^^^^^^^^^^^^^^^^^^^^^
  File "C:\Users\user\Desktop\p312\Lib\site-packages\django\db\utils.py", line 91, in __exit__
    raise dj_exc_value.with_traceback(traceback) from exc_value
  File "C:\Users\user\Desktop\p312\Lib\site-packages\django\db\backends\utils.py", line 105, in _execute
    return self.cursor.execute(sql, params)
           ^^^^^^^^^^^^^^^^^^^^^^^^^^^^^^^^
django.db.utils.IntegrityError: null value in column "price" of relation "dashboard_position" violates not-null constraint
DETAIL:  Failing row contains (37, 4281.44, 4375, 3000, 3000, d005aba4651f4d97a0b4ce6cece9d5a0, t, reaching_min_profit_exit_price, 0, f, 43.7, 598.6, null, 2037.16, 37.16, 1.86, 98.98, 85.03, 0, 1757085038, 1757409404, 0, t, 0.07, auto_exit_style_only_after_min_profit, 8, 0.46713208022382086).


2025-09-09 13:16:48.375458 - Traceback (most recent call last):
  File "C:\Users\user\Desktop\trade\dashboard\models\models_position.py", line 178, in evaluate
    if self.min_profit_exit_price < self.price:
       ^^^^^^^^^^^^^^^^^^^^^^^^^^^^^^^^^^^^^^^
TypeError: '<' not supported between instances of 'float' and 'NoneType'

During handling of the above exception, another exception occurred:

Traceback (most recent call last):
  File "C:\Users\user\Desktop\p312\Lib\site-packages\urllib3\connection.py", line 198, in _new_conn
    sock = connection.create_connection(
           ^^^^^^^^^^^^^^^^^^^^^^^^^^^^^
  File "C:\Users\user\Desktop\p312\Lib\site-packages\urllib3\util\connection.py", line 60, in create_connection
    for res in socket.getaddrinfo(host, port, family, socket.SOCK_STREAM):
               ^^^^^^^^^^^^^^^^^^^^^^^^^^^^^^^^^^^^^^^^^^^^^^^^^^^^^^^^^^
  File "C:\Users\user\AppData\Local\Programs\Python\Python312\Lib\socket.py", line 978, in getaddrinfo
    for res in _socket.getaddrinfo(host, port, family, type, proto, flags):
               ^^^^^^^^^^^^^^^^^^^^^^^^^^^^^^^^^^^^^^^^^^^^^^^^^^^^^^^^^^^
socket.gaierror: [Errno 11001] getaddrinfo failed

The above exception was the direct cause of the following exception:

Traceback (most recent call last):
  File "C:\Users\user\Desktop\p312\Lib\site-packages\urllib3\connectionpool.py", line 787, in urlopen
    response = self._make_request(
               ^^^^^^^^^^^^^^^^^^^
  File "C:\Users\user\Desktop\p312\Lib\site-packages\urllib3\connectionpool.py", line 488, in _make_request
    raise new_e
  File "C:\Users\user\Desktop\p312\Lib\site-packages\urllib3\connectionpool.py", line 464, in _make_request
    self._validate_conn(conn)
  File "C:\Users\user\Desktop\p312\Lib\site-packages\urllib3\connectionpool.py", line 1093, in _validate_conn
    conn.connect()
  File "C:\Users\user\Desktop\p312\Lib\site-packages\urllib3\connection.py", line 753, in connect
    self.sock = sock = self._new_conn()
                       ^^^^^^^^^^^^^^^^
  File "C:\Users\user\Desktop\p312\Lib\site-packages\urllib3\connection.py", line 205, in _new_conn
    raise NameResolutionError(self.host, self, e) from e
urllib3.exceptions.NameResolutionError: <urllib3.connection.HTTPSConnection object at 0x0000017CBB3AFBF0>: Failed to resolve 'api.telegram.org' ([Errno 11001] getaddrinfo failed)

The above exception was the direct cause of the following exception:

Traceback (most recent call last):
  File "C:\Users\user\Desktop\p312\Lib\site-packages\requests\adapters.py", line 667, in send
    resp = conn.urlopen(
           ^^^^^^^^^^^^^
  File "C:\Users\user\Desktop\p312\Lib\site-packages\urllib3\connectionpool.py", line 841, in urlopen
    retries = retries.increment(
              ^^^^^^^^^^^^^^^^^^
  File "C:\Users\user\Desktop\p312\Lib\site-packages\urllib3\util\retry.py", line 519, in increment
    raise MaxRetryError(_pool, url, reason) from reason  # type: ignore[arg-type]
    ^^^^^^^^^^^^^^^^^^^^^^^^^^^^^^^^^^^^^^^^^^^^^^^^^^^
urllib3.exceptions.MaxRetryError: HTTPSConnectionPool(host='api.telegram.org', port=443): Max retries exceeded with url: /bot8452876784:AAHzQeMZQGmEA8PcqXnGwdyh5y7dBYjiCwg/sendMessage?chat_id=5214991865&text=%3Cb%3Eruntime%20error%3C/b%3E%0A%0ATraceback%20(most%20recent%20call%20last):%0A%20%20File%20%22C:%5CUsers%5Cuser%5CDesktop%5Ctrade%5Cdashboard%5Cmodels%5Cmodels_position.py%22,%20line%20178,%20in%20evaluate%0A%20%20%20%20if%20self.min_profit_exit_price%20%3C%20self.price:%0A%20%20%20%20%20%20%20%5E%5E%5E%5E%5E%5E%5E%5E%5E%5E%5E%5E%5E%5E%5E%5E%5E%5E%5E%5E%5E%5E%5E%5E%5E%5E%5E%5E%5E%5E%5E%5E%5E%5E%5E%5E%5E%5E%5E%0ATypeError:%20'%3C'%20not%20supported%20between%20instances%20of%20'float'%20and%20'NoneType'%0A&parse_mode=HTML (Caused by NameResolutionError("<urllib3.connection.HTTPSConnection object at 0x0000017CBB3AFBF0>: Failed to resolve 'api.telegram.org' ([Errno 11001] getaddrinfo failed)"))

During handling of the above exception, another exception occurred:

Traceback (most recent call last):
  File "C:\Users\user\Desktop\trade\dashboard\modules\notification\notification.py", line 21, in send
    requests.get(url)
  File "C:\Users\user\Desktop\p312\Lib\site-packages\requests\api.py", line 73, in get
    return request("get", url, params=params, **kwargs)
           ^^^^^^^^^^^^^^^^^^^^^^^^^^^^^^^^^^^^^^^^^^^^
  File "C:\Users\user\Desktop\p312\Lib\site-packages\requests\api.py", line 59, in request
    return session.request(method=method, url=url, **kwargs)
           ^^^^^^^^^^^^^^^^^^^^^^^^^^^^^^^^^^^^^^^^^^^^^^^^^
  File "C:\Users\user\Desktop\p312\Lib\site-packages\requests\sessions.py", line 589, in request
    resp = self.send(prep, **send_kwargs)
           ^^^^^^^^^^^^^^^^^^^^^^^^^^^^^^
  File "C:\Users\user\Desktop\p312\Lib\site-packages\requests\sessions.py", line 703, in send
    r = adapter.send(request, **kwargs)
        ^^^^^^^^^^^^^^^^^^^^^^^^^^^^^^^
  File "C:\Users\user\Desktop\p312\Lib\site-packages\requests\adapters.py", line 700, in send
    raise ConnectionError(e, request=request)
requests.exceptions.ConnectionError: HTTPSConnectionPool(host='api.telegram.org', port=443): Max retries exceeded with url: /bot8452876784:AAHzQeMZQGmEA8PcqXnGwdyh5y7dBYjiCwg/sendMessage?chat_id=5214991865&text=%3Cb%3Eruntime%20error%3C/b%3E%0A%0ATraceback%20(most%20recent%20call%20last):%0A%20%20File%20%22C:%5CUsers%5Cuser%5CDesktop%5Ctrade%5Cdashboard%5Cmodels%5Cmodels_position.py%22,%20line%20178,%20in%20evaluate%0A%20%20%20%20if%20self.min_profit_exit_price%20%3C%20self.price:%0A%20%20%20%20%20%20%20%5E%5E%5E%5E%5E%5E%5E%5E%5E%5E%5E%5E%5E%5E%5E%5E%5E%5E%5E%5E%5E%5E%5E%5E%5E%5E%5E%5E%5E%5E%5E%5E%5E%5E%5E%5E%5E%5E%5E%0ATypeError:%20'%3C'%20not%20supported%20between%20instances%20of%20'float'%20and%20'NoneType'%0A&parse_mode=HTML (Caused by NameResolutionError("<urllib3.connection.HTTPSConnection object at 0x0000017CBB3AFBF0>: Failed to resolve 'api.telegram.org' ([Errno 11001] getaddrinfo failed)"))

2025-09-09 13:16:48.391128 - Traceback (most recent call last):
  File "C:\Users\user\Desktop\p312\Lib\site-packages\django\db\backends\utils.py", line 105, in _execute
    return self.cursor.execute(sql, params)
           ^^^^^^^^^^^^^^^^^^^^^^^^^^^^^^^^
psycopg2.errors.NotNullViolation: null value in column "price" of relation "dashboard_position" violates not-null constraint
DETAIL:  Failing row contains (37, 4281.44, 4375, 3000, 3000, d005aba4651f4d97a0b4ce6cece9d5a0, t, reaching_min_profit_exit_price, 0, f, 43.7, 598.6, null, 2037.16, 37.16, 1.86, 98.98, 85.03, 0, 1757085038, 1757409408, 0, t, 0.07, auto_exit_style_only_after_min_profit, 8, 0.46713208022382086).


The above exception was the direct cause of the following exception:

Traceback (most recent call last):
  File "C:\Users\user\Desktop\trade\dashboard\views_pages\pulse_handler.py", line 45, in handle_a_pulse
    position.save()
  File "C:\Users\user\Desktop\trade\dashboard\models\models_position.py", line 114, in save
    super(Position, self).save(*args, **kwargs)
  File "C:\Users\user\Desktop\p312\Lib\site-packages\django\db\models\base.py", line 902, in save
    self.save_base(
  File "C:\Users\user\Desktop\p312\Lib\site-packages\django\db\models\base.py", line 1008, in save_base
    updated = self._save_table(
              ^^^^^^^^^^^^^^^^^
  File "C:\Users\user\Desktop\p312\Lib\site-packages\django\db\models\base.py", line 1138, in _save_table
    updated = self._do_update(
              ^^^^^^^^^^^^^^^^
  File "C:\Users\user\Desktop\p312\Lib\site-packages\django\db\models\base.py", line 1203, in _do_update
    return filtered._update(values) > 0
           ^^^^^^^^^^^^^^^^^^^^^^^^
  File "C:\Users\user\Desktop\p312\Lib\site-packages\django\db\models\query.py", line 1286, in _update
    return query.get_compiler(self.db).execute_sql(ROW_COUNT)
           ^^^^^^^^^^^^^^^^^^^^^^^^^^^^^^^^^^^^^^^^^^^^^^^^^^
  File "C:\Users\user\Desktop\p312\Lib\site-packages\django\db\models\sql\compiler.py", line 2060, in execute_sql
    row_count = super().execute_sql(result_type)
                ^^^^^^^^^^^^^^^^^^^^^^^^^^^^^^^^
  File "C:\Users\user\Desktop\p312\Lib\site-packages\django\db\models\sql\compiler.py", line 1623, in execute_sql
    cursor.execute(sql, params)
  File "C:\Users\user\Desktop\p312\Lib\site-packages\django\db\backends\utils.py", line 122, in execute
    return super().execute(sql, params)
           ^^^^^^^^^^^^^^^^^^^^^^^^^^^^
  File "C:\Users\user\Desktop\p312\Lib\site-packages\django\db\backends\utils.py", line 79, in execute
    return self._execute_with_wrappers(
           ^^^^^^^^^^^^^^^^^^^^^^^^^^^^
  File "C:\Users\user\Desktop\p312\Lib\site-packages\django\db\backends\utils.py", line 92, in _execute_with_wrappers
    return executor(sql, params, many, context)
           ^^^^^^^^^^^^^^^^^^^^^^^^^^^^^^^^^^^^
  File "C:\Users\user\Desktop\p312\Lib\site-packages\django\db\backends\utils.py", line 100, in _execute
    with self.db.wrap_database_errors:
         ^^^^^^^^^^^^^^^^^^^^^^^^^^^^
  File "C:\Users\user\Desktop\p312\Lib\site-packages\django\db\utils.py", line 91, in __exit__
    raise dj_exc_value.with_traceback(traceback) from exc_value
  File "C:\Users\user\Desktop\p312\Lib\site-packages\django\db\backends\utils.py", line 105, in _execute
    return self.cursor.execute(sql, params)
           ^^^^^^^^^^^^^^^^^^^^^^^^^^^^^^^^
django.db.utils.IntegrityError: null value in column "price" of relation "dashboard_position" violates not-null constraint
DETAIL:  Failing row contains (37, 4281.44, 4375, 3000, 3000, d005aba4651f4d97a0b4ce6cece9d5a0, t, reaching_min_profit_exit_price, 0, f, 43.7, 598.6, null, 2037.16, 37.16, 1.86, 98.98, 85.03, 0, 1757085038, 1757409408, 0, t, 0.07, auto_exit_style_only_after_min_profit, 8, 0.46713208022382086).


2025-09-09 13:16:52.489648 - Traceback (most recent call last):
  File "C:\Users\user\Desktop\trade\dashboard\models\models_position.py", line 178, in evaluate
    if self.min_profit_exit_price < self.price:
       ^^^^^^^^^^^^^^^^^^^^^^^^^^^^^^^^^^^^^^^
TypeError: '<' not supported between instances of 'float' and 'NoneType'

During handling of the above exception, another exception occurred:

Traceback (most recent call last):
  File "C:\Users\user\Desktop\p312\Lib\site-packages\urllib3\connection.py", line 198, in _new_conn
    sock = connection.create_connection(
           ^^^^^^^^^^^^^^^^^^^^^^^^^^^^^
  File "C:\Users\user\Desktop\p312\Lib\site-packages\urllib3\util\connection.py", line 60, in create_connection
    for res in socket.getaddrinfo(host, port, family, socket.SOCK_STREAM):
               ^^^^^^^^^^^^^^^^^^^^^^^^^^^^^^^^^^^^^^^^^^^^^^^^^^^^^^^^^^
  File "C:\Users\user\AppData\Local\Programs\Python\Python312\Lib\socket.py", line 978, in getaddrinfo
    for res in _socket.getaddrinfo(host, port, family, type, proto, flags):
               ^^^^^^^^^^^^^^^^^^^^^^^^^^^^^^^^^^^^^^^^^^^^^^^^^^^^^^^^^^^
socket.gaierror: [Errno 11001] getaddrinfo failed

The above exception was the direct cause of the following exception:

Traceback (most recent call last):
  File "C:\Users\user\Desktop\p312\Lib\site-packages\urllib3\connectionpool.py", line 787, in urlopen
    response = self._make_request(
               ^^^^^^^^^^^^^^^^^^^
  File "C:\Users\user\Desktop\p312\Lib\site-packages\urllib3\connectionpool.py", line 488, in _make_request
    raise new_e
  File "C:\Users\user\Desktop\p312\Lib\site-packages\urllib3\connectionpool.py", line 464, in _make_request
    self._validate_conn(conn)
  File "C:\Users\user\Desktop\p312\Lib\site-packages\urllib3\connectionpool.py", line 1093, in _validate_conn
    conn.connect()
  File "C:\Users\user\Desktop\p312\Lib\site-packages\urllib3\connection.py", line 753, in connect
    self.sock = sock = self._new_conn()
                       ^^^^^^^^^^^^^^^^
  File "C:\Users\user\Desktop\p312\Lib\site-packages\urllib3\connection.py", line 205, in _new_conn
    raise NameResolutionError(self.host, self, e) from e
urllib3.exceptions.NameResolutionError: <urllib3.connection.HTTPSConnection object at 0x0000017CBB291FA0>: Failed to resolve 'api.telegram.org' ([Errno 11001] getaddrinfo failed)

The above exception was the direct cause of the following exception:

Traceback (most recent call last):
  File "C:\Users\user\Desktop\p312\Lib\site-packages\requests\adapters.py", line 667, in send
    resp = conn.urlopen(
           ^^^^^^^^^^^^^
  File "C:\Users\user\Desktop\p312\Lib\site-packages\urllib3\connectionpool.py", line 841, in urlopen
    retries = retries.increment(
              ^^^^^^^^^^^^^^^^^^
  File "C:\Users\user\Desktop\p312\Lib\site-packages\urllib3\util\retry.py", line 519, in increment
    raise MaxRetryError(_pool, url, reason) from reason  # type: ignore[arg-type]
    ^^^^^^^^^^^^^^^^^^^^^^^^^^^^^^^^^^^^^^^^^^^^^^^^^^^
urllib3.exceptions.MaxRetryError: HTTPSConnectionPool(host='api.telegram.org', port=443): Max retries exceeded with url: /bot8452876784:AAHzQeMZQGmEA8PcqXnGwdyh5y7dBYjiCwg/sendMessage?chat_id=5214991865&text=%3Cb%3Eruntime%20error%3C/b%3E%0A%0ATraceback%20(most%20recent%20call%20last):%0A%20%20File%20%22C:%5CUsers%5Cuser%5CDesktop%5Ctrade%5Cdashboard%5Cmodels%5Cmodels_position.py%22,%20line%20178,%20in%20evaluate%0A%20%20%20%20if%20self.min_profit_exit_price%20%3C%20self.price:%0A%20%20%20%20%20%20%20%5E%5E%5E%5E%5E%5E%5E%5E%5E%5E%5E%5E%5E%5E%5E%5E%5E%5E%5E%5E%5E%5E%5E%5E%5E%5E%5E%5E%5E%5E%5E%5E%5E%5E%5E%5E%5E%5E%5E%0ATypeError:%20'%3C'%20not%20supported%20between%20instances%20of%20'float'%20and%20'NoneType'%0A&parse_mode=HTML (Caused by NameResolutionError("<urllib3.connection.HTTPSConnection object at 0x0000017CBB291FA0>: Failed to resolve 'api.telegram.org' ([Errno 11001] getaddrinfo failed)"))

During handling of the above exception, another exception occurred:

Traceback (most recent call last):
  File "C:\Users\user\Desktop\trade\dashboard\modules\notification\notification.py", line 21, in send
    requests.get(url)
  File "C:\Users\user\Desktop\p312\Lib\site-packages\requests\api.py", line 73, in get
    return request("get", url, params=params, **kwargs)
           ^^^^^^^^^^^^^^^^^^^^^^^^^^^^^^^^^^^^^^^^^^^^
  File "C:\Users\user\Desktop\p312\Lib\site-packages\requests\api.py", line 59, in request
    return session.request(method=method, url=url, **kwargs)
           ^^^^^^^^^^^^^^^^^^^^^^^^^^^^^^^^^^^^^^^^^^^^^^^^^
  File "C:\Users\user\Desktop\p312\Lib\site-packages\requests\sessions.py", line 589, in request
    resp = self.send(prep, **send_kwargs)
           ^^^^^^^^^^^^^^^^^^^^^^^^^^^^^^
  File "C:\Users\user\Desktop\p312\Lib\site-packages\requests\sessions.py", line 703, in send
    r = adapter.send(request, **kwargs)
        ^^^^^^^^^^^^^^^^^^^^^^^^^^^^^^^
  File "C:\Users\user\Desktop\p312\Lib\site-packages\requests\adapters.py", line 700, in send
    raise ConnectionError(e, request=request)
requests.exceptions.ConnectionError: HTTPSConnectionPool(host='api.telegram.org', port=443): Max retries exceeded with url: /bot8452876784:AAHzQeMZQGmEA8PcqXnGwdyh5y7dBYjiCwg/sendMessage?chat_id=5214991865&text=%3Cb%3Eruntime%20error%3C/b%3E%0A%0ATraceback%20(most%20recent%20call%20last):%0A%20%20File%20%22C:%5CUsers%5Cuser%5CDesktop%5Ctrade%5Cdashboard%5Cmodels%5Cmodels_position.py%22,%20line%20178,%20in%20evaluate%0A%20%20%20%20if%20self.min_profit_exit_price%20%3C%20self.price:%0A%20%20%20%20%20%20%20%5E%5E%5E%5E%5E%5E%5E%5E%5E%5E%5E%5E%5E%5E%5E%5E%5E%5E%5E%5E%5E%5E%5E%5E%5E%5E%5E%5E%5E%5E%5E%5E%5E%5E%5E%5E%5E%5E%5E%0ATypeError:%20'%3C'%20not%20supported%20between%20instances%20of%20'float'%20and%20'NoneType'%0A&parse_mode=HTML (Caused by NameResolutionError("<urllib3.connection.HTTPSConnection object at 0x0000017CBB291FA0>: Failed to resolve 'api.telegram.org' ([Errno 11001] getaddrinfo failed)"))

2025-09-09 13:16:52.500644 - Traceback (most recent call last):
  File "C:\Users\user\Desktop\p312\Lib\site-packages\django\db\backends\utils.py", line 105, in _execute
    return self.cursor.execute(sql, params)
           ^^^^^^^^^^^^^^^^^^^^^^^^^^^^^^^^
psycopg2.errors.NotNullViolation: null value in column "price" of relation "dashboard_position" violates not-null constraint
DETAIL:  Failing row contains (37, 4281.44, 4375, 3000, 3000, d005aba4651f4d97a0b4ce6cece9d5a0, t, reaching_min_profit_exit_price, 0, f, 43.7, 598.6, null, 2037.16, 37.16, 1.86, 98.98, 85.03, 0, 1757085038, 1757409412, 0, t, 0.07, auto_exit_style_only_after_min_profit, 8, 0.46713208022382086).


The above exception was the direct cause of the following exception:

Traceback (most recent call last):
  File "C:\Users\user\Desktop\trade\dashboard\views_pages\pulse_handler.py", line 45, in handle_a_pulse
    position.save()
  File "C:\Users\user\Desktop\trade\dashboard\models\models_position.py", line 114, in save
    super(Position, self).save(*args, **kwargs)
  File "C:\Users\user\Desktop\p312\Lib\site-packages\django\db\models\base.py", line 902, in save
    self.save_base(
  File "C:\Users\user\Desktop\p312\Lib\site-packages\django\db\models\base.py", line 1008, in save_base
    updated = self._save_table(
              ^^^^^^^^^^^^^^^^^
  File "C:\Users\user\Desktop\p312\Lib\site-packages\django\db\models\base.py", line 1138, in _save_table
    updated = self._do_update(
              ^^^^^^^^^^^^^^^^
  File "C:\Users\user\Desktop\p312\Lib\site-packages\django\db\models\base.py", line 1203, in _do_update
    return filtered._update(values) > 0
           ^^^^^^^^^^^^^^^^^^^^^^^^
  File "C:\Users\user\Desktop\p312\Lib\site-packages\django\db\models\query.py", line 1286, in _update
    return query.get_compiler(self.db).execute_sql(ROW_COUNT)
           ^^^^^^^^^^^^^^^^^^^^^^^^^^^^^^^^^^^^^^^^^^^^^^^^^^
  File "C:\Users\user\Desktop\p312\Lib\site-packages\django\db\models\sql\compiler.py", line 2060, in execute_sql
    row_count = super().execute_sql(result_type)
                ^^^^^^^^^^^^^^^^^^^^^^^^^^^^^^^^
  File "C:\Users\user\Desktop\p312\Lib\site-packages\django\db\models\sql\compiler.py", line 1623, in execute_sql
    cursor.execute(sql, params)
  File "C:\Users\user\Desktop\p312\Lib\site-packages\django\db\backends\utils.py", line 122, in execute
    return super().execute(sql, params)
           ^^^^^^^^^^^^^^^^^^^^^^^^^^^^
  File "C:\Users\user\Desktop\p312\Lib\site-packages\django\db\backends\utils.py", line 79, in execute
    return self._execute_with_wrappers(
           ^^^^^^^^^^^^^^^^^^^^^^^^^^^^
  File "C:\Users\user\Desktop\p312\Lib\site-packages\django\db\backends\utils.py", line 92, in _execute_with_wrappers
    return executor(sql, params, many, context)
           ^^^^^^^^^^^^^^^^^^^^^^^^^^^^^^^^^^^^
  File "C:\Users\user\Desktop\p312\Lib\site-packages\django\db\backends\utils.py", line 100, in _execute
    with self.db.wrap_database_errors:
         ^^^^^^^^^^^^^^^^^^^^^^^^^^^^
  File "C:\Users\user\Desktop\p312\Lib\site-packages\django\db\utils.py", line 91, in __exit__
    raise dj_exc_value.with_traceback(traceback) from exc_value
  File "C:\Users\user\Desktop\p312\Lib\site-packages\django\db\backends\utils.py", line 105, in _execute
    return self.cursor.execute(sql, params)
           ^^^^^^^^^^^^^^^^^^^^^^^^^^^^^^^^
django.db.utils.IntegrityError: null value in column "price" of relation "dashboard_position" violates not-null constraint
DETAIL:  Failing row contains (37, 4281.44, 4375, 3000, 3000, d005aba4651f4d97a0b4ce6cece9d5a0, t, reaching_min_profit_exit_price, 0, f, 43.7, 598.6, null, 2037.16, 37.16, 1.86, 98.98, 85.03, 0, 1757085038, 1757409412, 0, t, 0.07, auto_exit_style_only_after_min_profit, 8, 0.46713208022382086).


2025-09-09 13:17:08.834349 - Traceback (most recent call last):
  File "C:\Users\user\Desktop\trade\dashboard\models\models_position.py", line 178, in evaluate
    if self.min_profit_exit_price < self.price:
       ^^^^^^^^^^^^^^^^^^^^^^^^^^^^^^^^^^^^^^^
TypeError: '<' not supported between instances of 'float' and 'NoneType'

During handling of the above exception, another exception occurred:

Traceback (most recent call last):
  File "C:\Users\user\Desktop\p312\Lib\site-packages\urllib3\connection.py", line 198, in _new_conn
    sock = connection.create_connection(
           ^^^^^^^^^^^^^^^^^^^^^^^^^^^^^
  File "C:\Users\user\Desktop\p312\Lib\site-packages\urllib3\util\connection.py", line 60, in create_connection
    for res in socket.getaddrinfo(host, port, family, socket.SOCK_STREAM):
               ^^^^^^^^^^^^^^^^^^^^^^^^^^^^^^^^^^^^^^^^^^^^^^^^^^^^^^^^^^
  File "C:\Users\user\AppData\Local\Programs\Python\Python312\Lib\socket.py", line 978, in getaddrinfo
    for res in _socket.getaddrinfo(host, port, family, type, proto, flags):
               ^^^^^^^^^^^^^^^^^^^^^^^^^^^^^^^^^^^^^^^^^^^^^^^^^^^^^^^^^^^
socket.gaierror: [Errno 11001] getaddrinfo failed

The above exception was the direct cause of the following exception:

Traceback (most recent call last):
  File "C:\Users\user\Desktop\p312\Lib\site-packages\urllib3\connectionpool.py", line 787, in urlopen
    response = self._make_request(
               ^^^^^^^^^^^^^^^^^^^
  File "C:\Users\user\Desktop\p312\Lib\site-packages\urllib3\connectionpool.py", line 488, in _make_request
    raise new_e
  File "C:\Users\user\Desktop\p312\Lib\site-packages\urllib3\connectionpool.py", line 464, in _make_request
    self._validate_conn(conn)
  File "C:\Users\user\Desktop\p312\Lib\site-packages\urllib3\connectionpool.py", line 1093, in _validate_conn
    conn.connect()
  File "C:\Users\user\Desktop\p312\Lib\site-packages\urllib3\connection.py", line 753, in connect
    self.sock = sock = self._new_conn()
                       ^^^^^^^^^^^^^^^^
  File "C:\Users\user\Desktop\p312\Lib\site-packages\urllib3\connection.py", line 205, in _new_conn
    raise NameResolutionError(self.host, self, e) from e
urllib3.exceptions.NameResolutionError: <urllib3.connection.HTTPSConnection object at 0x0000017CBB3ADB50>: Failed to resolve 'api.telegram.org' ([Errno 11001] getaddrinfo failed)

The above exception was the direct cause of the following exception:

Traceback (most recent call last):
  File "C:\Users\user\Desktop\p312\Lib\site-packages\requests\adapters.py", line 667, in send
    resp = conn.urlopen(
           ^^^^^^^^^^^^^
  File "C:\Users\user\Desktop\p312\Lib\site-packages\urllib3\connectionpool.py", line 841, in urlopen
    retries = retries.increment(
              ^^^^^^^^^^^^^^^^^^
  File "C:\Users\user\Desktop\p312\Lib\site-packages\urllib3\util\retry.py", line 519, in increment
    raise MaxRetryError(_pool, url, reason) from reason  # type: ignore[arg-type]
    ^^^^^^^^^^^^^^^^^^^^^^^^^^^^^^^^^^^^^^^^^^^^^^^^^^^
urllib3.exceptions.MaxRetryError: HTTPSConnectionPool(host='api.telegram.org', port=443): Max retries exceeded with url: /bot8452876784:AAHzQeMZQGmEA8PcqXnGwdyh5y7dBYjiCwg/sendMessage?chat_id=5214991865&text=%3Cb%3Eruntime%20error%3C/b%3E%0A%0ATraceback%20(most%20recent%20call%20last):%0A%20%20File%20%22C:%5CUsers%5Cuser%5CDesktop%5Ctrade%5Cdashboard%5Cmodels%5Cmodels_position.py%22,%20line%20178,%20in%20evaluate%0A%20%20%20%20if%20self.min_profit_exit_price%20%3C%20self.price:%0A%20%20%20%20%20%20%20%5E%5E%5E%5E%5E%5E%5E%5E%5E%5E%5E%5E%5E%5E%5E%5E%5E%5E%5E%5E%5E%5E%5E%5E%5E%5E%5E%5E%5E%5E%5E%5E%5E%5E%5E%5E%5E%5E%5E%0ATypeError:%20'%3C'%20not%20supported%20between%20instances%20of%20'float'%20and%20'NoneType'%0A&parse_mode=HTML (Caused by NameResolutionError("<urllib3.connection.HTTPSConnection object at 0x0000017CBB3ADB50>: Failed to resolve 'api.telegram.org' ([Errno 11001] getaddrinfo failed)"))

During handling of the above exception, another exception occurred:

Traceback (most recent call last):
  File "C:\Users\user\Desktop\trade\dashboard\modules\notification\notification.py", line 21, in send
    requests.get(url)
  File "C:\Users\user\Desktop\p312\Lib\site-packages\requests\api.py", line 73, in get
    return request("get", url, params=params, **kwargs)
           ^^^^^^^^^^^^^^^^^^^^^^^^^^^^^^^^^^^^^^^^^^^^
  File "C:\Users\user\Desktop\p312\Lib\site-packages\requests\api.py", line 59, in request
    return session.request(method=method, url=url, **kwargs)
           ^^^^^^^^^^^^^^^^^^^^^^^^^^^^^^^^^^^^^^^^^^^^^^^^^
  File "C:\Users\user\Desktop\p312\Lib\site-packages\requests\sessions.py", line 589, in request
    resp = self.send(prep, **send_kwargs)
           ^^^^^^^^^^^^^^^^^^^^^^^^^^^^^^
  File "C:\Users\user\Desktop\p312\Lib\site-packages\requests\sessions.py", line 703, in send
    r = adapter.send(request, **kwargs)
        ^^^^^^^^^^^^^^^^^^^^^^^^^^^^^^^
  File "C:\Users\user\Desktop\p312\Lib\site-packages\requests\adapters.py", line 700, in send
    raise ConnectionError(e, request=request)
requests.exceptions.ConnectionError: HTTPSConnectionPool(host='api.telegram.org', port=443): Max retries exceeded with url: /bot8452876784:AAHzQeMZQGmEA8PcqXnGwdyh5y7dBYjiCwg/sendMessage?chat_id=5214991865&text=%3Cb%3Eruntime%20error%3C/b%3E%0A%0ATraceback%20(most%20recent%20call%20last):%0A%20%20File%20%22C:%5CUsers%5Cuser%5CDesktop%5Ctrade%5Cdashboard%5Cmodels%5Cmodels_position.py%22,%20line%20178,%20in%20evaluate%0A%20%20%20%20if%20self.min_profit_exit_price%20%3C%20self.price:%0A%20%20%20%20%20%20%20%5E%5E%5E%5E%5E%5E%5E%5E%5E%5E%5E%5E%5E%5E%5E%5E%5E%5E%5E%5E%5E%5E%5E%5E%5E%5E%5E%5E%5E%5E%5E%5E%5E%5E%5E%5E%5E%5E%5E%0ATypeError:%20'%3C'%20not%20supported%20between%20instances%20of%20'float'%20and%20'NoneType'%0A&parse_mode=HTML (Caused by NameResolutionError("<urllib3.connection.HTTPSConnection object at 0x0000017CBB3ADB50>: Failed to resolve 'api.telegram.org' ([Errno 11001] getaddrinfo failed)"))

2025-09-09 13:17:08.839349 - Traceback (most recent call last):
  File "C:\Users\user\Desktop\p312\Lib\site-packages\django\db\backends\utils.py", line 105, in _execute
    return self.cursor.execute(sql, params)
           ^^^^^^^^^^^^^^^^^^^^^^^^^^^^^^^^
psycopg2.errors.NotNullViolation: null value in column "price" of relation "dashboard_position" violates not-null constraint
DETAIL:  Failing row contains (37, 4281.44, 4375, 3000, 3000, d005aba4651f4d97a0b4ce6cece9d5a0, t, reaching_min_profit_exit_price, 0, f, 43.7, 598.6, null, 2037.16, 37.16, 1.86, 98.98, 85.03, 0, 1757085038, 1757409428, 0, t, 0.07, auto_exit_style_only_after_min_profit, 8, 0.46713208022382086).


The above exception was the direct cause of the following exception:

Traceback (most recent call last):
  File "C:\Users\user\Desktop\trade\dashboard\views_pages\pulse_handler.py", line 45, in handle_a_pulse
    position.save()
  File "C:\Users\user\Desktop\trade\dashboard\models\models_position.py", line 114, in save
    super(Position, self).save(*args, **kwargs)
  File "C:\Users\user\Desktop\p312\Lib\site-packages\django\db\models\base.py", line 902, in save
    self.save_base(
  File "C:\Users\user\Desktop\p312\Lib\site-packages\django\db\models\base.py", line 1008, in save_base
    updated = self._save_table(
              ^^^^^^^^^^^^^^^^^
  File "C:\Users\user\Desktop\p312\Lib\site-packages\django\db\models\base.py", line 1138, in _save_table
    updated = self._do_update(
              ^^^^^^^^^^^^^^^^
  File "C:\Users\user\Desktop\p312\Lib\site-packages\django\db\models\base.py", line 1203, in _do_update
    return filtered._update(values) > 0
           ^^^^^^^^^^^^^^^^^^^^^^^^
  File "C:\Users\user\Desktop\p312\Lib\site-packages\django\db\models\query.py", line 1286, in _update
    return query.get_compiler(self.db).execute_sql(ROW_COUNT)
           ^^^^^^^^^^^^^^^^^^^^^^^^^^^^^^^^^^^^^^^^^^^^^^^^^^
  File "C:\Users\user\Desktop\p312\Lib\site-packages\django\db\models\sql\compiler.py", line 2060, in execute_sql
    row_count = super().execute_sql(result_type)
                ^^^^^^^^^^^^^^^^^^^^^^^^^^^^^^^^
  File "C:\Users\user\Desktop\p312\Lib\site-packages\django\db\models\sql\compiler.py", line 1623, in execute_sql
    cursor.execute(sql, params)
  File "C:\Users\user\Desktop\p312\Lib\site-packages\django\db\backends\utils.py", line 122, in execute
    return super().execute(sql, params)
           ^^^^^^^^^^^^^^^^^^^^^^^^^^^^
  File "C:\Users\user\Desktop\p312\Lib\site-packages\django\db\backends\utils.py", line 79, in execute
    return self._execute_with_wrappers(
           ^^^^^^^^^^^^^^^^^^^^^^^^^^^^
  File "C:\Users\user\Desktop\p312\Lib\site-packages\django\db\backends\utils.py", line 92, in _execute_with_wrappers
    return executor(sql, params, many, context)
           ^^^^^^^^^^^^^^^^^^^^^^^^^^^^^^^^^^^^
  File "C:\Users\user\Desktop\p312\Lib\site-packages\django\db\backends\utils.py", line 100, in _execute
    with self.db.wrap_database_errors:
         ^^^^^^^^^^^^^^^^^^^^^^^^^^^^
  File "C:\Users\user\Desktop\p312\Lib\site-packages\django\db\utils.py", line 91, in __exit__
    raise dj_exc_value.with_traceback(traceback) from exc_value
  File "C:\Users\user\Desktop\p312\Lib\site-packages\django\db\backends\utils.py", line 105, in _execute
    return self.cursor.execute(sql, params)
           ^^^^^^^^^^^^^^^^^^^^^^^^^^^^^^^^
django.db.utils.IntegrityError: null value in column "price" of relation "dashboard_position" violates not-null constraint
DETAIL:  Failing row contains (37, 4281.44, 4375, 3000, 3000, d005aba4651f4d97a0b4ce6cece9d5a0, t, reaching_min_profit_exit_price, 0, f, 43.7, 598.6, null, 2037.16, 37.16, 1.86, 98.98, 85.03, 0, 1757085038, 1757409428, 0, t, 0.07, auto_exit_style_only_after_min_profit, 8, 0.46713208022382086).


2025-09-09 13:28:54.140787 - --------> XXxXX pulses are being blocked.
2025-09-09 13:29:13.580251 - --------> XXxXX pulses are being blocked.
2025-09-09 13:31:36.607979 - --------> XXxXX pulses are being blocked.
2025-09-09 13:31:40.679451 - --------> XXxXX pulses are being blocked.
2025-09-09 13:31:44.738300 - --------> XXxXX pulses are being blocked.
2025-09-09 13:31:48.797327 - --------> XXxXX pulses are being blocked.
2025-09-09 13:35:07.629192 - initiating W3...
2025-09-09 13:35:07.651642 - uniswap fully initiated
2025-09-09 13:35:07.653643 - performing V3 Quote
2025-09-09 13:35:08.917187 - quote: 2037.551618
2025-09-09 13:35:08.919186 - performing V3 Quote
2025-09-09 13:35:09.520272 - quote: 2037.551618
2025-09-09 13:35:09.521271 - performing V3 Quote
2025-09-09 13:35:10.109078 - quote: 2037.551618
2025-09-09 13:35:10.111596 - slipage_to_fee: -0.00019076340163412964
2025-09-09 13:35:10.113595 - performing token_to_fiat: 0.46713208022382086 of weth -> usdc
2025-09-09 13:35:10.115595 - V3 got_weth: 0.46713208022382086
2025-09-09 13:35:10.117594 - <-> swapping 0.46713208022382086 weth for 2037.1630018560827 usdc -- fee_teir: 500
2025-09-09 13:35:10.121115 - building tx for action: exactInputSingle
2025-09-09 13:35:10.823422 - waiting for https://etherscan.io/tx/0x139ae5c34ff2f134779710d0113fd9b1542e4b83a04edfa92cdd2951944fa26e 

2025-09-09 13:35:37.974406 - ---------------> successful
2025-09-09 13:35:42.966165 - initiating W3...
2025-09-09 13:35:42.984716 - uniswap fully initiated
2025-09-09 13:35:42.986711 - performing V3 Quote
2025-09-09 13:35:44.275424 - quote: 977.637949
2025-09-09 13:35:44.276423 - performing V3 Quote
2025-09-09 13:35:44.876959 - quote: 977.637949
2025-09-09 13:35:44.877959 - performing V3 Quote
2025-09-09 13:35:45.481010 - quote: 977.637949
2025-09-09 13:35:45.493523 - slipage_to_fee: -0.00010028529185528124
2025-09-09 13:35:45.495524 - performing token_to_fiat: 0.224203317414029 of weth -> usdc
2025-09-09 13:35:45.497528 - V3 got_weth: 0.224203317414029
2025-09-09 13:35:45.498524 - <-> swapping 0.224203317414029 weth for 977.5399161242113 usdc -- fee_teir: 500
2025-09-09 13:35:45.500036 - building tx for action: exactInputSingle
2025-09-09 13:35:46.214842 - waiting for https://etherscan.io/tx/0x6914a6f3d2d0123a317d13b07fedf2f64f90864b5e90ab3545eae56a820a8fde 

2025-09-09 13:36:01.187065 - ---------------> successful
